Workbook

Sheet M&A
C2: Netflix Warner Brothers M&A Model
C3: In millions, except per share data
C5: Date | D5: 46104
C6: Tax Structure | D6: Stock Sale
C8: TRANSACTION ASSUMPTIONS | F8: SOURCES & USES OF FUNDS | I8: ACCRETION/DILUTION ANALYSIS
C10: Acquirer | F10: Sources of Funds | I10: EPS Accounting: | J10: GAAP EPS | M10: 2026 | N10: 2027 | O10: 2028 | P10: 2029 | Q10: 2030
C11: Name | D11: Netflix | F11: New borrowing to acquire target | G11: =D50 -> 22983.534 | M11: =EOMONTH(L11,12) -> 397 | N11: =EOMONTH(M11,12) -> 762 | O11: =EOMONTH(N11,12) -> 1127 | P11: =EOMONTH(O11,12) -> 1492 | Q11: =EOMONTH(P11,12) -> 1858
C12: Ticker | D12: NASDAQ: NFLX | F12: New borrowing to refinance target debt | G12: =D55 -> 32428 | I12: Acquirer
C13: Latest Fiscal Year End Date | D13: 46022 | F13: Cash used to acquire target | G13: =D51 -> 5745.8835 | I13: Net income | M13: ='Acquirer Financials'!I27 -> 13536.447 | N13: ='Acquirer Financials'!J27 -> 15881.033 | O13: ='Acquirer Financials'!K27 -> 18161.911 | P13: ='Acquirer Financials'!L27 -> 20333.34 | Q13: ='Acquirer Financials'!M27 -> 22816.336
C14: Latest Filing Date | D14: 46045 | F14: Value of stock issued to acquire target | G14: =D31*D28 -> 43094.126 | I14: =J10 -> GAAP EPS | M14: =IF($J$10="GAAP EPS",'Acquirer Financials'!I227,'Acquirer Financials'!I234) -> 3.1926939 | N14: =IF($J$10="GAAP EPS",'Acquirer Financials'!J227,'Acquirer Financials'!J234) -> 3.7406187 | O14: =IF($J$10="GAAP EPS",'Acquirer Financials'!K227,'Acquirer Financials'!K234) -> 4.2736667 | P14: =IF($J$10="GAAP EPS",'Acquirer Financials'!L227,'Acquirer Financials'!L234) -> 4.7811343 | Q14: =IF($J$10="GAAP EPS",'Acquirer Financials'!M227,'Acquirer Financials'!M234) -> 5.3614511
C15: Filing Type | D15: 10-K | F15: Cash for fees | G15: =D39+D63 -> 636.17539 | I15: Diluted shares outstanding | M15: ='Acquirer Financials'!I226 -> 4239.8199 | N15: ='Acquirer Financials'!J226 -> 4245.5633 | O15: ='Acquirer Financials'!K226 -> 4249.7258 | P15: ='Acquirer Financials'!L226 -> 4252.8277 | Q15: ='Acquirer Financials'!M226 -> 4255.6269
C16: Current Share Price | D16: 93.38 | F16: Total sources | G16: =SUM(G11:G15) -> 104887.72
I17: Target
C18: Target | F18: Uses of Funds | I18: Net income | M18: ='Target Financials'!I31 -> -477.39566 | N18: ='Target Financials'!J31 -> 939.94184 | O18: ='Target Financials'!K31 -> 1277.1121 | P18: ='Target Financials'!L31 -> 1605.2706 | Q18: ='Target Financials'!M31 -> 1775.729
C19: Name | D19: Warner Brothers | F19: Stock to target | G19: =D16*D33 -> 43094.126 | I19: =J10 -> GAAP EPS | M19: =IF($J$10="GAAP EPS",'Target Financials'!I255,'Target Financials'!I261) -> -0.18315193 | N19: =IF($J$10="GAAP EPS",'Target Financials'!J255,'Target Financials'!J261) -> 0.3653954 | O19: =IF($J$10="GAAP EPS",'Target Financials'!K255,'Target Financials'!K261) -> 0.49046415 | P19: =IF($J$10="GAAP EPS",'Target Financials'!L255,'Target Financials'!L261) -> 0.61715748 | Q19: =IF($J$10="GAAP EPS",'Target Financials'!M255,'Target Financials'!M261) -> 0.68309406
C20: Ticker | D20: NASDAQ: WBD | F20: Cash to target | G20: =D32*D28 -> 28729.417 | I20: Diluted shares outstanding | M20: ='Target Financials'!I254 -> 2606.5554 | N20: ='Target Financials'!J254 -> 2572.3965 | O20: ='Target Financials'!K254 -> 2603.8847 | P20: ='Target Financials'!L254 -> 2601.0713 | Q20: ='Target Financials'!M254 -> 2599.538
C21: Latest Fiscal Year End Date | D21: 46022 | F21: Target debt refinanced | G21: =D55 -> 32428
C22: Latest Filing Date | D22: 46080 | F22: Deal fees | G22: =D39 -> 359.11772 | I22: Transaction related expenses/income
C23: Filing Type | D23: 10-K | F23: Financing fees | G23: =D63 -> 277.05767 | I23: Less: Interest expense from new deal debt | M23: =-$D$56*$D$65 -> -2864.15 | N23: =-$D$56*$D$65 -> -2864.15 | O23: =-$D$56*$D$65 -> -2864.15 | P23: =-$D$56*$D$65 -> -2864.15 | Q23: =-$D$56*$D$65 -> -2864.15
C24: Current Share Price | D24: 27.4 | F24: Total Uses | G24: =SUM(G19:G23) -> 104887.72 | I24: Less: Interest income on cash forgone | M24: =-($G$15+$G$13)*$D$66 -> -201.94116 | N24: =-($G$15+$G$13)*$D$66 -> -201.94116 | O24: =-($G$15+$G$13)*$D$66 -> -201.94116 | P24: =-($G$15+$G$13)*$D$66 -> -201.94116 | Q24: =-($G$15+$G$13)*$D$66 -> -201.94116
C25: % offer premium | D25: =D26/D24-1 -> 0.012773723 | I25: Plus: Synergies | M25: =$D$40 -> 3000 | N25: =$D$40 -> 3000 | O25: =$D$40 -> 3000 | P25: =$D$40 -> 3000 | Q25: =$D$40 -> 3000
C26: Offer Price per Share | D26: 27.75 | I26: Less: Incremental D&A expense | M26: =IF($J$10="GAAP EPS",-($G$34+$G$41),0) -> -5251.2725 | N26: =IF($J$10="GAAP EPS",-($G$34+$G$41),0) -> -5251.2725 | O26: =IF($J$10="GAAP EPS",-($G$34+$G$41),0) -> -5251.2725 | P26: =IF($J$10="GAAP EPS",-($G$34+$G$41),0) -> -5251.2725 | Q26: =IF($J$10="GAAP EPS",-($G$34+$G$41),0) -> -5251.2725
C27: Diluted Shares Outstanding | D27: =Shares!G31 -> 2588.2358 | F27: WRITE-UPS & PURCHASE PRICE ALLOCATION | I27: Taxes (assumed at acquirer's rate) | M27: =-SUM(M23:M26)*$D$44 -> 753.47044 | N27: =-SUM(N23:N26)*$D$44 -> 753.47044 | O27: =-SUM(O23:O26)*$D$44 -> 753.47044 | P27: =-SUM(P23:P26)*$D$44 -> 753.47044 | Q27: =-SUM(Q23:Q26)*$D$44 -> 753.47044
C28: Offer Value | D28: =D26*D27 -> 71823.543 | I28: Total after tax transaction related income/ (expenses) | M28: =SUM(M23:M27) -> -4563.8933 | N28: =SUM(N23:N27) -> -4563.8933 | O28: =SUM(O23:O27) -> -4563.8933 | P28: =SUM(P23:P27) -> -4563.8933 | Q28: =SUM(Q23:Q27) -> -4563.8933
F29: Asset Write-Ups
C30: Deal Structure | F30: Book value of target PP&E | G30: ='Target Financials'!I62 -> 6691.2317 | I30: ="Pro Forma "&LEFT(J10,FIND(" ",J10)-1)&" Net Income" -> Pro Forma GAAP Net Income | M30: ='Pro Forma Financials'!D31 -> 10986.366 | N30: ='Pro Forma Financials'!E31 -> 15216.943 | O30: ='Pro Forma Financials'!F31 -> 17923.85 | P30: ='Pro Forma Financials'!G31 -> 20473.027 | Q30: ='Pro Forma Financials'!H31 -> 23150.51
C31: % Stock | D31: 0.6 | F31: % Write-up | G31: 0.2 | I31: Pro Forma Shares Outstanding | M31: =M15+$D$33 -> 4701.3119 | N31: =N15+$D$33 -> 4707.0553 | O31: =O15+$D$33 -> 4711.2178 | P31: =P15+$D$33 -> 4714.3197 | Q31: =Q15+$D$33 -> 4717.1189
C32: % Cash | D32: =1-D31 -> 0.4 | F32: Asset write-up | G32: =G30*G31 -> 1338.2463
C33: Acquirer Shares Issued in Transaction | D33: =D31*D28/D16 -> 461.49203 | F33: Useful life | G33: ='Target Financials'!D188 -> 8 | I33: ="Pro forma "&J10 -> Pro forma GAAP EPS | M33: =M30/M31 -> 2.3368723 | N33: =N30/N31 -> 3.2327946 | O33: =O30/O31 -> 3.8045046 | P33: =P30/P31 -> 4.3427321 | Q33: =Q30/Q31 -> 4.9077648
C34: Nominal Exchange Ratio (offer price/acq share price) | D34: =D26/D16 -> 0.29717284 | F34: Incremental depreciation expense | G34: =G32/G33 -> 167.28079 | I34: Acquirer standalone EPS | M34: =M14 -> 3.1926939 | N34: =N14 -> 3.7406187 | O34: =O14 -> 4.2736667 | P34: =P14 -> 4.7811343 | Q34: =Q14 -> 5.3614511
C35: Actual exchange ratio (% stock x offer price/acq share price) | D35: =D31*D26/D16 -> 0.17830371 | F35: Incremental deferred tax liabilities | G35: =IF($D$6="Stock sale",G32*D44,0) -> 189.62951 | I35: Accretion / Dilution per share | M35: =M33-M34 -> -0.85582162 | N35: =N33-N34 -> -0.50782407 | O35: =O33-O34 -> -0.46916205 | P35: =P33-P34 -> -0.43840224 | Q35: =Q33-Q34 -> -0.4536863
I36: Accretion / Dilution % | M36: =M35/M34 -> -0.26805627 | N36: =N35/N34 -> -0.13575938 | O36: =O35/O34 -> -0.10977975 | P36: =P35/P34 -> -0.091694191 | Q36: =Q35/Q34 -> -0.084620058
C37: Other Assumptions | F37: Book value of target intangible assets | G37: ='Target Financials'!I64 -> 47049.129 | I37: Additional pretax synergies required to breakeven | M37: =MAX(0,-(M35*M31/(1-$D$44))) -> 4687.7367 | N37: =MAX(0,-(N35*N31/(1-$D$44))) -> 2784.9889 | O37: =MAX(0,-(O35*O31/(1-$D$44))) -> 2575.2355 | P37: =MAX(0,-(P35*P31/(1-$D$44))) -> 2407.979 | Q37: =MAX(0,-(Q35*Q31/(1-$D$44))) -> 2493.4082
C38: Deal Fees as % of offer value | D38: 0.005 | F38: % Write-up | G38: 1.1
C39: Deal Fees | D39: =D38*D28 -> 359.11772 | F39: Asset write-up | G39: =G37*G38 -> 51754.042
C40: Assumed annual pretax cost synergies | D40: 3000 | F40: Useful life | G40: ='Target Financials'!H64/-'Target Financials'!H206 -> 10.179805 | I40: SENSITIVITY ANALYSIS
C41: Assumed annual revenue synergies | D41: 2500 | F41: Incremental amortization expense | G41: =G39/G40 -> 5083.9917
C42: Netflix FY2026 EBITDA | D42: ='Acquirer Financials'!I36 -> 35249.954 | F42: Incremental deferred tax liabilities | G42: =IF($D$6="Stock sale",G39*D44,0) -> 7333.5478 | I42: Accretion/Dilution Year 1 | K42: % Stock | L42: Offer Price
C43: Warner Bros FY2026 EBITDA | D43: ='Target Financials'!I39 -> 5658.6058 | K43: =M35 -> -0.85582162 | L43: 18 | M43: =L43+4 -> 22 | N43: =M43+4 -> 26 | O43: =N43+4 -> 30 | P43: =O43+4 -> 34 | Q43: =P43+4 -> 38
C44: Acquirer Tax Rate (2026E) | D44: ='Acquirer Financials'!I48 -> 0.1417 | F44: Purchase Price Allocation | I44: Current share price | K44: 1 | L44: -0.63896017 | M44: -0.70674582 | N44: -0.77150138 | O44: -0.83342558 | P44: -0.89270014 | Q44: -0.94949158
...

Sheet Target Financials
C2: Warner Bros Discovery Financial Statement Model
C3: In millions, except per share data
C5: Circ Break 1 = off, 0 = on | D5: 1
C6: Latest Fiscal Year End Date | D6: ='M&A'!D21 -> 46022
C7: Shares Outstanding | D7: 2479.9295
B9: x | C9: INCOME STATEMENT
C10: Fiscal Year | D10: 2021 | E10: 2022 | F10: 2023 | G10: 2024 | H10: 2025 | I10: 2026 | J10: 2027 | K10: 2028 | L10: 2029 | M10: 2030
C11: End Date | D11: 44561 | E11: =EOMONTH(D11,12) -> 44926 | F11: =EOMONTH(E11,12) -> 45291 | G11: =EOMONTH(F11,12) -> 45657 | H11: =EOMONTH(G11,12) -> 46022 | I11: =EOMONTH(H11,12) -> 46387 | J11: =EOMONTH(I11,12) -> 46752 | K11: =EOMONTH(J11,12) -> 47118 | L11: =EOMONTH(K11,12) -> 47483 | M11: =EOMONTH(L11,12) -> 47848
C13: Revenue | D13: 12191 | E13: 33817 | F13: 41321 | G13: 39321 | H13: 37296 | I13: 37432.15 | J13: 38125.5 | K13: 38743.39 | L13: 38824.97 | M13: 39336.82
C14: Cost of revenue | D14: -4620 | E14: -20442 | F14: -24526 | G14: -22970 | H14: -20885 | I14: =I15-I13 -> -21748.079 | J14: =J15-J13 -> -21617.159 | K14: =K15-K13 -> -22664.883 | L14: =L15-L13 -> -22906.732 | M14: =M15-M13 -> -23366.071
C15: Gross profit | D15: =SUM(D13:D14) -> 7571 | E15: =SUM(E13:E14) -> 13375 | F15: =SUM(F13:F14) -> 16795 | G15: =SUM(G13:G14) -> 16351 | H15: =SUM(H13:H14) -> 16411 | I15: =I13*I45 -> 15684.071 | J15: =J13*J45 -> 16508.341 | K15: =K13*K45 -> 16078.507 | L15: =L13*L45 -> 15918.238 | M15: =M13*M45 -> 15970.749
C16: SG&A | D16: -4016 | E16: -9678 | F16: -9696 | G16: -9296 | H16: -9418 | I16: =I13*-I47 -> -9452.3806 | J16: =J13*-J47 -> -9627.4657 | K16: =K13*-K47 -> -9783.4955 | L16: =L13*-L47 -> -9804.0961 | M16: =M13*-M47 -> -9933.3486
C17: Depreciation and amortization | D17: -1582 | E17: -7193 | F17: -7985 | G17: -7037 | H17: -5684 | I17: =-I197+I206 -> -5102.8902 | J17: =-J197+J206 -> -4150.5525 | K17: =-K197+K206 -> -3474.3439 | L17: =-L197+L206 -> -3246.3361 | M17: =-M197+M206 -> -3104.7617
C18: Restructuring charges | D18: -32 | E18: -3757 | F18: -585 | G18: -447 | H18: -399 | I18: =I13*-I49 -> -400.45656 | J18: =J13*-J49 -> -407.87416 | K18: =K13*-K49 -> -414.48447 | L18: =L13*-L49 -> -415.35722 | M18: =M13*-M49 -> -420.8331
C19: Impairments and loss on dispositions | D19: 71 | E19: -117 | F19: -77 | G19: -9603 | H19: -172 | I19: =I13*-I50 -> -172.62789 | J19: =J13*-J50 -> -175.82545 | K19: =K13*-K50 -> -178.67501 | L19: =L13*-L50 -> -179.05123 | M19: =M13*-M50 -> -181.41176
C20: Total operating expenses | D20: =SUM(D16:D19) -> -5559 | E20: =SUM(E16:E19) -> -20745 | F20: =SUM(F16:F19) -> -18343 | G20: =SUM(G16:G19) -> -26383 | H20: =SUM(H16:H19) -> -15673 | I20: =SUM(I16:I19) -> -15128.355 | J20: =SUM(J16:J19) -> -14361.718 | K20: =SUM(K16:K19) -> -13850.999 | ... M20: =SUM(M16:M19) -> -13640.355
C21: Operating income (EBIT) | D21: =D15+D20 -> 2012 | E21: =E15+E20 -> -7370 | F21: =F15+F20 -> -1548 | G21: =G15+G20 -> -10032 | H21: =H15+H20 -> 738 | I21: =I15+I20 -> 555.71551 | J21: =J15+J20 -> 2146.6237 | K21: =K15+K20 -> 2227.508 | ... M21: =M15+M20 -> 2330.3937
C22: Interest expense, net | D22: -633 | E22: -1777 | F22: -2221 | G22: -2017 | H22: -2085 | I22: =-I230 -> -1968.95 | J22: =-J230 -> -1708.19 | K22: =-K230 -> -1288.9 | L22: =-L230 -> -897 | M22: =-M230 -> -736
C23: Interest income | D23: 18 | E23: 67 | F23: 179 | G23: 210 | H23: 206 | I23: =I233 -> 199.01155 | J23: =J233 -> 188.04138 | K23: =K233 -> 170.74148 | L23: =L233 -> 170.49703 | M23: =M233 -> 179.7783
C24: Other income (expense), net | D24: 36 | E24: 120 | F24: -273 | G24: 451 | H24: 2780 | I24: =AVERAGE(D24:H24) -> 622.8 | J24: =I24 -> 622.8 | K24: =J24 -> 622.8 | L24: =K24 -> 622.8 | M24: =L24 -> 622.8
C25: Total other income/expense | D25: =SUM(D22:D24) -> -579 | E25: =SUM(E22:E24) -> -1590 | F25: =SUM(F22:F24) -> -2315 | G25: =SUM(G22:G24) -> -1356 | H25: =SUM(H22:H24) -> 901 | I25: =SUM(I22:I24) -> -1147.1384 | J25: =SUM(J22:J24) -> -897.34862 | K25: =SUM(K22:K24) -> -495.35852 | ... M25: =SUM(M22:M24) -> 66.578296
C26: Income (loss) before income taxes | D26: =D21+D25 -> 1433 | E26: =E21+E25 -> -8960 | F26: =F21+F25 -> -3863 | G26: =G21+G25 -> -11388 | H26: =H21+H25 -> 1639 | I26: =I21+I25 -> -591.42294 | J26: =J21+J25 -> 1249.2751 | K26: =K21+K25 -> 1732.1495 | ... M26: =M21+M25 -> 2396.972
C27: Income tax expense | D27: -236 | E27: 1663 | F27: 784 | G27: -94 | H27: -890 | I27: =-I52*I26 -> 136.02728 | J27: =-J52*J26 -> -287.33328 | K27: =-K52*K26 -> -433.03737 | L27: =-L52*L26 -> -542.42353 | M27: =-M52*M26 -> -599.243
C28: Net income | D28: =SUM(D26:D27) -> 1197 | E28: =SUM(E26:E27) -> -7297 | F28: =SUM(F26:F27) -> -3079 | G28: =SUM(G26:G27) -> -11482 | H28: =SUM(H26:H27) -> 749 | I28: =SUM(I26:I27) -> -455.39566 | J28: =SUM(J26:J27) -> 961.94184 | K28: =SUM(K26:K27) -> 1299.1121 | ... M28: =SUM(M26:M27) -> 1797.729
C29: Net income attributable to noncontrolling interests | D29: -138 | E29: -68 | F29: -38 | G29: 129 | H29: -24 | I29: =H29 -> -24 | J29: =I29 -> -24 | K29: =J29 -> -24 | L29: =K29 -> -24 | M29: =L29 -> -24
C30: Net income attributable to redeemable noncontrolling interests | D30: -53 | E30: -6 | F30: -9 | G30: 42 | H30: 2 | I30: =H30 -> 2 | J30: =I30 -> 2 | K30: =J30 -> 2 | L30: =K30 -> 2 | M30: =L30 -> 2
C31: Net income available to Warner Bros | D31: =SUM(D28:D30) -> 1006 | E31: =SUM(E28:E30) -> -7371 | F31: =SUM(F28:F30) -> -3126 | G31: =SUM(G28:G30) -> -11311 | H31: =SUM(H28:H30) -> 727 | I31: =SUM(I28:I30) -> -477.39566 | J31: =SUM(J28:J30) -> 939.94184 | K31: =SUM(K28:K30) -> 1277.1121 | ... M31: =SUM(M28:M30) -> 1775.729
C33: Basic EPS | D33: 1.55 | E33: -3.82 | F33: -1.28 | G33: -4.62 | H33: 0.29 | I33: =I252 -> -0.1914699 | J33: =J252 -> 0.38222058 | K33: =K252 -> 0.51276279 | L33: =L252 -> 0.64524788 | M33: =M252 -> 0.7142048
C34: Diluted EPS | D34: 1.54 | E34: -3.82 | F34: -1.28 | G34: -4.62 | H34: 0.29 | I34: =I255 -> -0.18315193 | J34: =J255 -> 0.3653954 | K34: =K255 -> 0.49046415 | L34: =L255 -> 0.61715748 | M34: =M255 -> 0.68309406
C36: Basic weighted average shares outstanding | D36: 588 | E36: 1940 | F36: 2436 | G36: 2450 | H36: 2475 | I36: =I251 -> 2493.3196 | J36: =J251 -> 2459.1607 | K36: =K251 -> 2490.6489 | L36: =L251 -> 2487.8355 | M36: =M251 -> 2486.3022
C37: Diluted weighted average shares outstanding | D37: 664 | E37: 1940 | F37: 2436 | G37: 2450 | H37: 2530 | I37: =I254 -> 2606.5554 | J37: =J254 -> 2572.3965 | K37: =K254 -> 2603.8847 | L37: =L254 -> 2601.0713 | M37: =M254 -> 2599.538
C39: EBITDA | D39: =D21-D17 -> 3594 | E39: =E21-E17 -> -177 | F39: =F21-F17 -> 6437 | G39: =G21-G17 -> -2995 | H39: =H21-H17 -> 6422 | I39: =I21-I17 -> 5658.6058 | J39: =J21-J17 -> 6297.1762 | K39: =K21-K17 -> 5701.8519 | ... M39: =M21-M17 -> 5435.1554
C40: Stock-based compensation | D40: 178 | E40: 412 | F40: 500 | G40: 557 | H40: 769 | I40: =H40*(1+I44) -> 771.80725 | J40: =I40*(1+J44) -> 786.10332 | K40: =J40*(1+K44) -> 798.84349 | L40: =K40*(1+L44) -> 800.52558 | M40: =L40*(1+M44) -> 811.07933
C41: Adjusted EBITDA | D41: =SUM(D39:D40) -> 3772 | E41: =SUM(E39:E40) -> 235 | F41: =SUM(F39:F40) -> 6937 | G41: =SUM(G39:G40) -> -2438 | H41: =SUM(H39:H40) -> 7191 | I41: =SUM(I39:I40) -> 6430.413 | J41: =SUM(J39:J40) -> 7083.2796 | K41: =SUM(K39:K40) -> 6500.6954 | ... M41: =SUM(M39:M40) -> 6246.2348
C43: Growth rate and margins
C44: Revenue growth % | E44: =E13/D13-1 -> 1.7739316 | F44: =F13/E13-1 -> 0.22190023 | G44: =G13/F13-1 -> -0.048401539 | H44: =H13/G13-1 -> -0.051499199 | I44: =I13/H13-1 -> 0.0036505255 | J44: =J13/I13-1 -> 0.018522847 | K44: =K13/J13-1 -> 0.016206738 | L44: =L13/K13-1 -> 0.0021056495 | M44: =M13/L13-1 -> 0.013183526
C45: Gross margin % | D45: =D15/D13 -> 0.62103191 | E45: =E15/E13 -> 0.39551113 | F45: =F15/F13 -> 0.40645193 | G45: =G15/G13 -> 0.41583378 | H45: =H15/H13 -> 0.44002038 | I45: 0.419 | J45: 0.433 | K45: 0.415 | L45: 0.41 | M45: 0.406
C47: SG&A % of sales | D47: =-D16/D13 -> 0.32942335 | E47: =-E16/E13 -> 0.28618742 | F47: =-F16/F13 -> 0.23465066 | G47: =-G16/G13 -> 0.23641311 | H47: =-H16/H13 -> 0.25252038 | I47: =H47 -> 0.25252038 | J47: =I47 -> 0.25252038 | K47: =J47 -> 0.25252038 | L47: =K47 -> 0.25252038 | M47: =L47 -> 0.25252038
C48: D&A % of sales | D48: =-D17/D13 -> 0.12976786 | E48: =-E17/E13 -> 0.21270367 | F48: =-F17/F13 -> 0.19324315 | G48: =-G17/G13 -> 0.1789629 | H48: =-H17/H13 -> 0.1524024 | I48: =H48 -> 0.1524024 | J48: =-J17/J13 -> 0.10886552 | K48: =-K17/K13 -> 0.089675785 | L48: =-L17/L13 -> 0.083614644 | M48: =-M17/M13 -> 0.078927623
C49: Restructuring charges % of sales | D49: =-D18/D13 -> 0.0026248872 | E49: =-E18/E13 -> 0.11109797 | F49: =-F18/F13 -> 0.01415745 | G49: =-G18/G13 -> 0.011367971 | H49: =-H18/H13 -> 0.010698198 | I49: =H49 -> 0.010698198 | J49: =I49 -> 0.010698198 | K49: =J49 -> 0.010698198 | L49: =K49 -> 0.010698198 | M49: =L49 -> 0.010698198
...

Sheet Acquirer Financials
C2: Netflix Financial Statement Model
C3: In millions, except per share data
C5: Circ Break 1 = off, 0 = on | D5: 1
C6: Latest Fiscal Year End Date | D6: ='M&A'!D13 -> 46022
C7: Shares Outstanding | D7: 4222.1622
B9: x | C9: INCOME STATEMENT
C10: Fiscal Year | D10: 2021 | E10: 2022 | F10: 2023 | G10: 2024 | H10: 2025 | I10: 2026 | J10: 2027 | K10: 2028 | L10: 2029 | M10: 2030
C11: End Date | D11: 44561 | E11: =EOMONTH(D11,12) -> 44926 | F11: =EOMONTH(E11,12) -> 45291 | G11: =EOMONTH(F11,12) -> 45657 | H11: =EOMONTH(G11,12) -> 46022 | I11: =EOMONTH(H11,12) -> 46387 | J11: =EOMONTH(I11,12) -> 46752 | K11: =EOMONTH(J11,12) -> 47118 | L11: =EOMONTH(K11,12) -> 47483 | M11: =EOMONTH(L11,12) -> 47848
C13: Revenue | D13: 29697.844 | E13: 31615.55 | F13: 33723.297 | G13: 39000.966 | H13: 45183.036 | I13: 51365.94 | J13: 57402.33 | K13: 63205.96 | L13: 69022.09 | M13: 74516.56
C14: Cost of revenue | D14: -17332.683 | E14: -19168.285 | F14: -19715.368 | G14: -21038.464 | H14: -23275.329 | I14: =I15-I13 -> -25421.004 | J14: =J15-J13 -> -27650.702 | K14: =K15-K13 -> -29580.389 | L14: =L15-L13 -> -31694.944 | M14: =M15-M13 -> -33249.289
C15: Gross profit | D15: =SUM(D13:D14) -> 12365.161 | E15: =SUM(E13:E14) -> 12447.265 | F15: =SUM(F13:F14) -> 14007.929 | G15: =SUM(G13:G14) -> 17962.502 | H15: =SUM(H13:H14) -> 21907.707 | I15: =I13*I42 -> 25944.936 | J15: =J13*J42 -> 29751.628 | K15: =K13*K42 -> 33625.571 | L15: =L13*L42 -> 37327.146 | M15: =M13*M42 -> 41267.271
C16: Sales and marketing | D16: -2545.146 | E16: -2530.502 | F16: -2657.883 | G16: -2917.554 | H16: -3301.306 | I16: =I$13*-I44 -> -3753.0609 | J16: =J$13*-J44 -> -4194.1107 | K16: =K$13*-K44 -> -4618.1539 | L16: =L$13*-L44 -> -5043.1104 | M16: =M$13*-M44 -> -5444.5648
C17: Tech and development | D17: -2273.885 | E17: -2711.041 | F17: -2675.758 | G17: -2925.295 | H17: -3391.39 | I17: =I$13*-I45 -> -3855.4721 | J17: =J$13*-J45 -> -4308.557 | K17: =K$13*-K45 -> -4744.1713 | L17: =L$13*-L45 -> -5180.7237 | M17: =M$13*-M45 -> -5593.1327
C18: General and administrative | D18: -1351.621 | E18: -1572.891 | F18: -1720.285 | G18: -1702.039 | H18: -1888.408 | I18: =I$13*-I46 -> -2146.8201 | J18: =J$13*-J46 -> -2399.1088 | K18: =K$13*-K46 -> -2641.6693 | L18: =L$13*-L46 -> -2884.7523 | M18: =M$13*-M46 -> -3114.3916
C19: Total operating expenses | D19: =SUM(D16:D18) -> -6170.652 | E19: =SUM(E16:E18) -> -6814.434 | F19: =SUM(F16:F18) -> -7053.926 | G19: =SUM(G16:G18) -> -7544.888 | H19: =SUM(H16:H18) -> -8581.104 | I19: =SUM(I16:I18) -> -9755.3532 | J19: =SUM(J16:J18) -> -10901.777 | K19: =SUM(K16:K18) -> -12003.995 | ... M19: =SUM(M16:M18) -> -14152.089
C20: Operating income (EBIT) | D20: =D15+D19 -> 6194.509 | E20: =E15+E19 -> 5632.831 | F20: =F15+F19 -> 6954.003 | G20: =G15+G19 -> 10417.614 | H20: =H15+H19 -> 13326.603 | I20: =I15+I19 -> 16189.583 | J20: =J15+J19 -> 18849.851 | K20: =K15+K19 -> 21621.576 | ... M20: =M15+M19 -> 27115.182
C21: Interest expense | D21: -765.62 | E21: -706.212 | F21: -699.826 | G21: -718.733 | H21: -776.51 | I21: =-I202 -> -747.56516 | J21: =-J202 -> -747.56516 | K21: =-K202 -> -747.56516 | L21: =-L202 -> -747.56516 | M21: =-M202 -> -747.56516
C22: Interest income | D22: 8.214 | E22: 60 | F22: 281 | G22: 294 | H22: 295 | I22: =I205 -> 289.05817 | J22: =J205 -> 332.47006 | K22: =K205 -> 452.78896 | L22: =L205 -> 646.31826 | M22: =M205 -> 917.18147
C23: Other income (expense), net | D23: 403 | E23: 277.31 | F23: -329.772 | G23: -27.224 | H23: -122.541 | I23: =AVERAGE(D23:H23) -> 40.1546 | J23: =I23 -> 40.1546 | K23: =J23 -> 40.1546 | L23: =K23 -> 40.1546 | M23: =L23 -> 40.1546
C24: Total other income/expense | D24: =SUM(D21:D23) -> -354.406 | E24: =SUM(E21:E23) -> -368.902 | F24: =SUM(F21:F23) -> -748.598 | G24: =SUM(G21:G23) -> -451.957 | H24: =SUM(H21:H23) -> -604.051 | I24: =SUM(I21:I23) -> -418.35238 | J24: =SUM(J21:J23) -> -374.9405 | K24: =SUM(K21:K23) -> -254.62159 | ... M24: =SUM(M21:M23) -> 209.77091
C25: Income (loss) before income taxes | D25: =D20+D24 -> 5840.103 | E25: =E20+E24 -> 5263.929 | F25: =F20+F24 -> 6205.405 | G25: =G20+G24 -> 9965.657 | H25: =H20+H24 -> 12722.552 | I25: =I20+I24 -> 15771.231 | J25: =J20+J24 -> 18474.911 | K25: =K20+K24 -> 21366.955 | ... M25: =M20+M24 -> 27324.953
C26: Income tax expense | D26: -723.875 | E26: -772.005 | F26: -797.415 | G26: -1254.026 | H26: -1741.351 | I26: =-I48*I25 -> -2234.7834 | J26: =-J48*J25 -> -2593.8774 | K26: =-K48*K25 -> -3205.0432 | L26: =-L48*L25 -> -3824.1271 | M26: =-M48*M25 -> -4508.6172
C27: Net income | D27: =SUM(D25:D26) -> 5116.228 | E27: =SUM(E25:E26) -> 4491.924 | F27: =SUM(F25:F26) -> 5407.99 | G27: =SUM(G25:G26) -> 8711.631 | H27: =SUM(H25:H26) -> 10981.201 | I27: =SUM(I25:I26) -> 13536.447 | J27: =SUM(J25:J26) -> 15881.033 | K27: =SUM(K25:K26) -> 18161.911 | ... M27: =SUM(M25:M26) -> 22816.336
C29: Basic EPS | D29: 11.55 | E29: 10.1 | F29: 1.22 | G29: 2.03 | H29: 2.58 | I29: =I224 -> 3.2349104 | J29: =J224 -> 3.7900125 | K29: =K224 -> 4.3300432 | L29: =L224 -> 4.8441586 | M29: =M224 -> 5.4320779
C30: Diluted EPS | D30: 11.24 | E30: 9.95 | F30: 1.2 | G30: 1.98 | H30: 2.53 | I30: =I227 -> 3.1926939 | J30: =J227 -> 3.7406187 | K30: =K227 -> 4.2736667 | L30: =L227 -> 4.7811343 | M30: =M227 -> 5.3614511
C32: Basic weighted average shares outstanding | D32: 443.155 | E32: 444.698 | F32: 4415.712 | G32: 4295.191 | H32: 4249.512 | I32: =I223 -> 4184.4891 | J32: =J223 -> 4190.2324 | K32: =K223 -> 4194.395 | L32: =L223 -> 4197.4968 | M32: =M223 -> 4200.2961
C33: Diluted weighted average shares outstanding | D33: 455.372 | E33: 451.29 | F33: 4494.966 | G33: 4392.608 | H33: 4343.863 | I33: =I226 -> 4239.8199 | J33: =J226 -> 4245.5633 | K33: =K226 -> 4249.7258 | L33: =L226 -> 4252.8277 | M33: =M226 -> 4255.6269
C35: Depreciation and amortization | D35: =-D151-D178 -> 12438.779 | E35: =-E151-E178 -> 14362.814 | F35: =-F151-F178 -> 14554.384 | G35: =-G151-G178 -> 15630.431 | H35: =-H151-H178 -> 16755.555 | I35: =-I151-I178 -> 19060.371 | J35: =-J151-J178 -> 21279.236 | K35: =-K151-K178 -> 23434.853 | ... M35: =-M151-M178 -> 27692.369
C36: EBITDA | D36: =D20+D35 -> 18633.288 | E36: =E20+E35 -> 19995.645 | F36: =F20+F35 -> 21508.387 | G36: =G20+G35 -> 26048.045 | H36: =H20+H35 -> 30082.158 | I36: =I20+I35 -> 35249.954 | J36: =J20+J35 -> 40129.087 | K36: =K20+K35 -> 45056.429 | ... M36: =M20+M35 -> 54807.551
C37: Stock-based compensation | D37: 403.22 | E37: 575.452 | F37: 339.368 | G37: 272.588 | H37: 368.449 | I37: =H37*(1+I41) -> 418.86803 | J37: =I37*(1+J41) -> 468.0923 | K37: =J37*(1+K41) -> 515.4185 | L37: =K37*(1+L41) -> 562.84664 | M37: =L37*(1+M41) -> 607.65177
C38: Adjusted EBITDA | D38: =SUM(D36:D37) -> 19036.508 | E38: =SUM(E36:E37) -> 20571.097 | F38: =SUM(F36:F37) -> 21847.755 | G38: =SUM(G36:G37) -> 26320.633 | H38: =SUM(H36:H37) -> 30450.607 | I38: =SUM(I36:I37) -> 35668.822 | J38: =SUM(J36:J37) -> 40597.18 | K38: =SUM(K36:K37) -> 45571.847 | ... M38: =SUM(M36:M37) -> 55415.203
C40: Growth rate and margins
C41: Revenue growth % | E41: =E13/D13-1 -> 0.064573913 | F41: =F13/E13-1 -> 0.066668048 | G41: =G13/F13-1 -> 0.1564992 | H41: =H13/G13-1 -> 0.15851069 | I41: =I13/H13-1 -> 0.13684127 | J41: =J13/I13-1 -> 0.11751737 | K41: =K13/J13-1 -> 0.10110443 | L41: =L13/K13-1 -> 0.092018696 | M41: =M13/L13-1 -> 0.079604515
C42: Gross margin % | D42: =D15/D13 -> 0.41636561 | E42: =E15/E13 -> 0.39370705 | F42: =F15/F13 -> 0.4153784 | G42: =G15/G13 -> 0.46056557 | H42: =H15/H13 -> 0.48486576 | I42: 0.5051 | J42: 0.5183 | K42: 0.532 | L42: 0.5408 | M42: 0.5538
C44: Sales and marketing % of sales | D44: =-D16/D13 -> 0.085701373 | E44: =-E16/E13 -> 0.080039791 | F44: =-F16/F13 -> 0.078814447 | G44: =-G16/G13 -> 0.074807224 | H44: =-H16/H13 -> 0.073065165 | I44: =H44 -> 0.073065165 | J44: =I44 -> 0.073065165 | K44: =J44 -> 0.073065165 | L44: =K44 -> 0.073065165 | M44: =L44 -> 0.073065165
C45: Tech and development % of sales | D45: =-D17/D13 -> 0.076567343 | E45: =-E17/E13 -> 0.08575024 | F45: =-F17/F13 -> 0.079344496 | G45: =-G17/G13 -> 0.075005706 | H45: =-H17/H13 -> 0.075058923 | I45: =H45 -> 0.075058923 | J45: =I45 -> 0.075058923 | K45: =J45 -> 0.075058923 | L45: =K45 -> 0.075058923 | M45: =L45 -> 0.075058923
C46: General and administrative % of sales | D46: =-D18/D13 -> 0.045512428 | E46: =-E18/E13 -> 0.04975055 | F46: =-F18/F13 -> 0.051011768 | G46: =-G18/G13 -> 0.043640945 | H46: =-H18/H13 -> 0.041794624 | I46: =H46 -> 0.041794624 | J46: =I46 -> 0.041794624 | K46: =J46 -> 0.041794624 | L46: =K46 -> 0.041794624 | M46: =L46 -> 0.041794624
C48: Effective tax rate | D48: =-D26/D25 -> 0.12394901 | E48: =-E26/E25 -> 0.14665946 | F48: =-F26/F25 -> 0.1285033 | G48: =-G26/G25 -> 0.12583475 | H48: =-H26/H25 -> 0.1368712 | I48: 0.1417 | J48: 0.1404 | K48: 0.15 | L48: 0.1583 | M48: 0.165
B51: x | C51: BALANCE SHEET
C52: Fiscal Year | D52: 2021 | E52: 2022 | F52: 2023 | G52: 2024 | H52: 2025 | I52: 2026 | J52: 2027 | K52: 2028 | L52: 2029 | M52: 2030
...

Sheet Pro Forma Financials
C2: Pro Forma Financial Statements
C3: In millions, except per share data
B5: x | C5: INCOME STATEMENT
C6: Fiscal Year | D6: 2026 | E6: 2027 | F6: 2028 | G6: 2029 | H6: 2030
C7: End Date | D7: 46387 | E7: =EOMONTH(D7,12) -> 46752 | F7: =EOMONTH(E7,12) -> 47118 | G7: =EOMONTH(F7,12) -> 47483 | H7: =EOMONTH(G7,12) -> 47848
C9: Revenue | D9: ='Target Financials'!I13+'Acquirer Financials'!I13+'M&A'!$D$41 -> 91298.09 | E9: ='Target Financials'!J13+'Acquirer Financials'!J13+'M&A'!$D$41 -> 98027.83 | F9: ='Target Financials'!K13+'Acquirer Financials'!K13+'M&A'!$D$41 -> 104449.35 | G9: ='Target Financials'!L13+'Acquirer Financials'!L13+'M&A'!$D$41 -> 110347.06 | H9: ='Target Financials'!M13+'Acquirer Financials'!M13+'M&A'!$D$41 -> 116353.38
C10: Revenue growth % | D10: =D9/('Target Financials'!H13+'Acquirer Financials'!H13)-1 -> 0.10692479 | E10: =E9/D9-1 -> 0.073711728 | F10: =F9/E9-1 -> 0.065507112 | G10: =G9/F9-1 -> 0.056464784 | H10: =H9/G9-1 -> 0.054431174
C11: Cost of revenue | D11: ='Target Financials'!I14+'Acquirer Financials'!I14 -> -47169.083 | E11: ='Target Financials'!J14+'Acquirer Financials'!J14 -> -49267.861 | F11: ='Target Financials'!K14+'Acquirer Financials'!K14 -> -52245.272 | G11: ='Target Financials'!L14+'Acquirer Financials'!L14 -> -54601.676 | H11: ='Target Financials'!M14+'Acquirer Financials'!M14 -> -56615.36
C12: Cost of revenue as % of revenue | D12: =-D11/D9 -> 0.51664917 | E12: =-E11/E9 -> 0.50259055 | F12: =-F11/F9 -> 0.5001972 | G12: =-G11/G9 -> 0.49481768 | H12: =-H11/H9 -> 0.48658114
C13: Gross profit | D13: =D9+D11 -> 44129.007 | E13: =E9+E11 -> 48759.969 | F13: =F9+F11 -> 52204.078 | G13: =G9+G11 -> 55745.384 | H13: =H9+H11 -> 59738.02
C14: Gross profit margin | D14: =D13/D9 -> 0.48335083 | E14: =E13/E9 -> 0.49740945 | F14: =F13/F9 -> 0.4998028 | G14: =G13/G9 -> 0.50518232 | H14: =H13/H9 -> 0.51341886
C15: Operating expenses | D15: ='Target Financials'!I20+'Acquirer Financials'!I19-'M&A'!G22 -> -25242.826 | E15: ='Target Financials'!J20+'Acquirer Financials'!J19 -> -25263.494 | F15: ='Target Financials'!K20+'Acquirer Financials'!K19 -> -25854.993 | G15: ='Target Financials'!L20+'Acquirer Financials'!L19 -> -26753.427 | H15: ='Target Financials'!M20+'Acquirer Financials'!M19 -> -27792.444
C16: Operating expenses as % of revenue | D16: =-D15/D9 -> 0.276488 | E16: =-E15/E9 -> 0.25771757 | F16: =-F15/F9 -> 0.24753618 | G16: =-G15/G9 -> 0.24244803 | H16: =-H15/H9 -> 0.23886237
C17: Incremental Depreciation and Amortization | D17: =-('M&A'!$G$34+'M&A'!$G$41) -> -5251.2725 | E17: =-('M&A'!$G$34+'M&A'!$G$41) -> -5251.2725 | F17: =-('M&A'!$G$34+'M&A'!$G$41) -> -5251.2725 | G17: =-('M&A'!$G$34+'M&A'!$G$41) -> -5251.2725 | H17: =-('M&A'!$G$34+'M&A'!$G$41) -> -5251.2725
C18: Incremental D&A as % of OPEX | D18: =D17/D15 -> 0.20803029 | E18: =E17/E15 -> 0.2078601 | F18: =F17/F15 -> 0.20310477 | G18: =G17/G15 -> 0.19628411 | H18: =H17/H15 -> 0.18894605
C19: Cost synergies | D19: ='M&A'!$D$40 -> 3000 | E19: ='M&A'!$D$40 -> 3000 | F19: ='M&A'!$D$40 -> 3000 | G19: ='M&A'!$D$40 -> 3000 | H19: ='M&A'!$D$40 -> 3000
C20: Cost synergies as % of OPEX | D20: =-D19/D15 -> 0.11884565 | E20: =-E19/E15 -> 0.11874842 | F20: =-F19/F15 -> 0.11603175 | G20: =-G19/G15 -> 0.11213517 | H20: =-H19/H15 -> 0.10794301
C21: EBIT | D21: =SUM(D13,D15,D17,D19) -> 16634.908 | E21: =SUM(E13,E15,E17,E19) -> 21245.202 | F21: =SUM(F13,F15,F17,F19) -> 24097.812 | G21: =SUM(G13,G15,G17,G19) -> 26740.684 | H21: =SUM(H13,H15,H17,H19) -> 29694.303
C22: EBIT Margin | D22: =D21/D9 -> 0.18220434 | E22: =E21/E9 -> 0.21672623 | F22: =F21/F9 -> 0.23071289 | G22: =G21/G9 -> 0.24233255 | H22: =H21/H9 -> 0.25520791
C23: Interest expense | D23: ='Target Financials'!I22+'Acquirer Financials'!I21+'M&A'!M23+D37 -> -5636.0767 | E23: ='Target Financials'!J22+'Acquirer Financials'!J21+'M&A'!N23+E37 -> -5375.3167 | F23: ='Target Financials'!K22+'Acquirer Financials'!K21+'M&A'!O23+F37 -> -4956.0267 | G23: ='Target Financials'!L22+'Acquirer Financials'!L21+'M&A'!P23+G37 -> -4564.1267 | H23: ='Target Financials'!M22+'Acquirer Financials'!M21+'M&A'!Q23+H37 -> -4403.1267
C24: Interest income | D24: ='Target Financials'!I23+'Acquirer Financials'!I22+'M&A'!M24 -> 286.12856 | E24: ='Target Financials'!J23+'Acquirer Financials'!J22+'M&A'!N24 -> 318.57028 | F24: ='Target Financials'!K23+'Acquirer Financials'!K22+'M&A'!O24 -> 421.58928 | G24: ='Target Financials'!L23+'Acquirer Financials'!L22+'M&A'!P24 -> 614.87412 | H24: ='Target Financials'!M23+'Acquirer Financials'!M22+'M&A'!Q24 -> 895.0186
C25: Other income (expense) | D25: ='Target Financials'!I24+'Acquirer Financials'!I23 -> 662.9546 | E25: ='Target Financials'!J24+'Acquirer Financials'!J23 -> 662.9546 | F25: ='Target Financials'!K24+'Acquirer Financials'!K23 -> 662.9546 | G25: ='Target Financials'!L24+'Acquirer Financials'!L23 -> 662.9546 | H25: ='Target Financials'!M24+'Acquirer Financials'!M23 -> 662.9546
C26: EBT | D26: =D21+SUM(D23:D25) -> 11947.915 | E26: =E21+SUM(E23:E25) -> 16851.41 | F26: =F21+SUM(F23:F25) -> 20226.329 | G26: =G21+SUM(G23:G25) -> 23454.386 | H26: =H21+SUM(H23:H25) -> 26849.15
C27: EBT Margin | D27: =D26/D9 -> 0.13086708 | E27: =E26/E9 -> 0.17190435 | F27: =F26/F9 -> 0.19364724 | G27: =G26/G9 -> 0.21255108 | H27: =H26/H9 -> 0.23075522
C28: Income tax expense | D28: =D26*-D29+'M&A'!M27 -> -939.5491 | E28: =E26*-E29+'M&A'!N27 -> -1612.4676 | F28: =F26*-F29+'M&A'!O27 -> -2280.4789 | G28: =G26*-G29+'M&A'!P27 -> -2959.3589 | H28: =H26*-H29+'M&A'!Q27 -> -3676.6392
C29: Effective tax rate | D29: ='Acquirer Financials'!I48 -> 0.1417 | E29: ='Acquirer Financials'!J48 -> 0.1404 | F29: ='Acquirer Financials'!K48 -> 0.15 | G29: ='Acquirer Financials'!L48 -> 0.1583 | H29: ='Acquirer Financials'!M48 -> 0.165
C30: Net income attributable to noncontrolling interests | D30: ='Target Financials'!I29+'Target Financials'!I30 -> -22 | E30: ='Target Financials'!J29+'Target Financials'!J30 -> -22 | F30: ='Target Financials'!K29+'Target Financials'!K30 -> -22 | G30: ='Target Financials'!L29+'Target Financials'!L30 -> -22 | H30: ='Target Financials'!M29+'Target Financials'!M30 -> -22
C31: Net income | D31: =D26+D28+D30 -> 10986.366 | E31: =E26+E28+E30 -> 15216.943 | F31: =F26+F28+F30 -> 17923.85 | G31: =G26+G28+G30 -> 20473.027 | H31: =H26+H28+H30 -> 23150.51
C32: Net income margin | D32: =D31/D9 -> 0.12033511 | E32: =E31/E9 -> 0.15523084 | F32: =F31/F9 -> 0.17160327 | G32: =G31/G9 -> 0.18553306 | H32: =H31/H9 -> 0.19896723
C35: Financing Fee Amortization
C36: Beginning financing fees | D36: ='M&A'!D63 -> 277.05767 | E36: =D38 -> 221.64614 | F36: =E38 -> 166.2346 | G36: =F38 -> 110.82307 | H36: =G38 -> 55.411534
C37: Amortization | D37: ='M&A'!$D$63/-'M&A'!$D$61 -> -55.411534 | E37: ='M&A'!$D$63/-'M&A'!$D$61 -> -55.411534 | F37: ='M&A'!$D$63/-'M&A'!$D$61 -> -55.411534 | G37: ='M&A'!$D$63/-'M&A'!$D$61 -> -55.411534 | H37: ='M&A'!$D$63/-'M&A'!$D$61 -> -55.411534
C38: Ending financing fees | D38: =SUM(D36:D37) -> 221.64614 | E38: =SUM(E36:E37) -> 166.2346 | F38: =SUM(F36:F37) -> 110.82307 | G38: =SUM(G36:G37) -> 55.411534 | H38: =SUM(H36:H37) -> 0
B41: x | C41: BALANCE SHEET ADJUSTMENTS
D42: Standalone | F42: Adjustments | H42: Pro Forma
D43: Warner Bros | E43: Neflix | F43: Increase | G43: (Decrease) | H43: 46387
C45: Cash and cash equivalents | D45: ='Target Financials'!I59 -> 4976.8937 | E45: ='Acquirer Financials'!I55 -> 9208.1732 | G45: =-('M&A'!G13+'M&A'!G15) -> -6382.0588 | H45: =SUM(D45:G45) -> 7803.0081
C46: Account receivables, net | D46: ='Target Financials'!I60 -> 5313.3259 | E46: 0 | H46: =SUM(D46:G46) -> 5313.3259
C47: Prepaid expenses and other current assets | D47: ='Target Financials'!I61 -> 3358.2147 | E47: ='Acquirer Financials'!I56 -> 4499.4268 | H47: =SUM(D47:G47) -> 7857.6414
C48: Property and equipment, net | D48: ='Target Financials'!I62 -> 6691.2317 | E48: ='Acquirer Financials'!I58 -> 2395.772 | F48: ='M&A'!G32 -> 1338.2463 | H48: =SUM(D48:G48) -> 10425.25
...

Sheet Shares
C2: Shares
C3: In millions, except per share data
D4: Target | I4: Acquirer
D5: Warner Bros | I5: Netflix
C7: Basic share count | G7: ='Target Financials'!D7 -> 2479.9295 | L7: ='Acquirer Financials'!D7 -> 4222.1622
C8: RSUs/PSUs | G8: 97 | L8: 1.58526
C9: Total Basic Share Count | G9: =SUM(G7:G8) -> 2576.9295 | L9: =SUM(L7:L8) -> 4223.7474
C11: Options count | G11: 46.1 | L11: 127.6798
C12: Weighted average exercise price | G12: 20.68 | L12: 34.07
C13: # of options exercised | G13: =IF(G12<'M&A'!D24,Shares!G11,0) -> 46.1 | L13: =IF(L12<'M&A'!D16,Shares!L11,0) -> 127.6798
C14: Option proceeds | G14: =G12*G13 -> 953.348 | L14: =L12*L13 -> 4350.0509
C15: Shares repurchased | G15: =G14/'M&A'!D24 -> 34.793723 | L15: =L14/'M&A'!D16 -> 46.584396
C16: Net Dilution from Options | G16: =G13-G15 -> 11.306277 | L16: =L13-L15 -> 81.095408
C18: Convertible debt outstanding | G18: 0 | L18: 0
C19: Conversion ratio | G19: 0 | L19: 0
C20: Conversion price | G20: 0 | L20: 0
C21: Common shares convertible into | G21: 0 | L21: 0
C22: Dilution from convertible debt | G22: 0 | L22: 0
C24: Convertible preferred par value | G24: 0 | L24: 0
C25: Preferred shares oustanding | G25: 0 | L25: 0
C26: Conversion ratio | G26: 0 | L26: 0
C27: Common shares convertible into | G27: 0 | L27: 0
C28: Conversion price | G28: 0 | L28: 0
C29: Dilution from preferred stock | G29: 0 | L29: 0
C31: Fully Diluted Shares Outstanding | G31: =G9+G16+G22+G29 -> 2588.2358 | L31: =L9+L16+L22+L29 -> 4304.8428
