Workbook

Sheet Dashboard
C2: Palantir Technologies
C3: Dashboard
C4: $ USD thousands unless stated otherwise
C6: GENERAL
C8: Ticker | D8: PLTR | H8: Active Case: | I8: Base
C9: Date | D9: 46093
C10: Share Price | D10: 153.5
C12: VALUATION SUMMARY
C15: Valuation Methodology | D15: Low | E15: Difference | F15: High | J15: Summary | K15: Price | L15: Weighting
C16: Comps Value from FY1 mean-median range EV/EBITDA | D16: =(Valuation!Q15*FSM!R32+DCF!N60)/DCF!S60 -> 366.6819 | E16: =F16-D16 -> 115.4389 | F16: =(Valuation!Q14*FSM!R32+DCF!N60)/DCF!S60 -> 482.1208 | J16: Comps | K16: =(Valuation!Q15*FSM!R32+DCF!N60)/DCF!S60 -> 366.6819 | L16: 0.3
C17: DCF Value at 2%-4.5% Perpetuity Range at 10.16% WACC | D17: =DCF!E79 -> 76.147046 | E17: =F17-D17 -> 24.919789 | F17: =DCF!J79 -> 101.06683 | J17: DCF - Gordon Growth | K17: =DCF!D69 -> 88.873239 | L17: 0.35
C18: DCF Value at 30x-40x Exit EBITDA Range at 10.16% WACC | D18: =DCF!E90 -> 185.56646 | E18: =F18-D18 -> 53.886225 | F18: =DCF!J90 -> 239.45269 | J18: DCF - Exit Multiple | K18: =DCF!E69 -> 217.34229 | L18: 0.35
J19: Average | K19: =SUMPRODUCT(K16:K18,L16:L18) -> 217.18001
J20: Upside | K20: =K19/D10-1 -> 0.41485347

Sheet Rev Build
C2: Revenue Build
C3: $USD Thousand except per share data
B5: x | C5: Fiscal Year | D5: 2021 | E5: 2022 | F5: 2023 | G5: 2024 | H5: 2025 | I5: 2026 | J5: 2027 | K5: 2028 | L5: 2029 | M5: 2030 | N5: 2031 | O5: 2032 | P5: 2033 | Q5: 2034 | R5: 2035
C6: End Date | D6: 44561 | E6: =EOMONTH(D6,12) -> 44926 | F6: =EOMONTH(E6,12) -> 45291 | G6: =EOMONTH(F6,12) -> 45657 | H6: =EOMONTH(G6,12) -> 46022 | I6: =EOMONTH(H6,12) -> 46387 | J6: =EOMONTH(I6,12) -> 46752 | K6: =EOMONTH(J6,12) -> 47118 | L6: =EOMONTH(K6,12) -> 47483 | ... R6: =EOMONTH(Q6,12) -> 49674
C8: U.S Commercial | E8: 335100 | F8: 457100 | G8: 702300 | H8: 1500000 | I8: =H8*(1+I9) -> 2518167.6 | J8: =I8*(1+J9) -> 4101536.8 | K8: =J8*(1+K9) -> 6475417.6 | L8: =K8*(1+L9) -> 9899478.4 | M8: =L8*(1+M9) -> 14639134 | N8: =M8*(1+N9) -> 20916079 | O8: =N8*(1+O9) -> 28838637 | P8: =O8*(1+P9) -> 38320157 | ... R8: =Q8*(1+R9) -> 60213811
C9: U.S Commercial Growth % | F9: =F8/E8-1 -> 0.36407043 | G9: =G8/F8-1 -> 0.53642529 | H9: =H8/G8-1 -> 1.1358394 | I9: =I28 -> 0.67877837 | J9: =J28 -> 0.62877837 | K9: =K28 -> 0.57877837 | L9: =L28 -> 0.52877837 | M9: =M28 -> 0.47877837 | N9: =N28 -> 0.42877837 | O9: =O28 -> 0.37877837 | P9: =P28 -> 0.32877837 | ... R9: =R28 -> 0.22877837
C11: International Commercial | E11: 498995 | F11: 545697 | G11: 593602 | H11: 573159 | I11: =H11*(1+I12) -> 601232.33 | J11: =I11*(1+J12) -> 627674.54 | K11: =J11*(1+K12) -> 652141.3 | L11: =K11*(1+L12) -> 674301.07 | M11: =L11*(1+M12) -> 693842.32 | N11: =M11*(1+N12) -> 710480.67 | O11: =N11*(1+O12) -> 723965.6 | P11: =O11*(1+P12) -> 734086.64 | ... R11: =Q11*(1+R12) -> 743626.66
C12: International Commercial Growth % | F12: =F11/E11-1 -> 0.09359212 | G12: =G11/F11-1 -> 0.087786812 | H12: =H11/G11-1 -> -0.0344389 | I12: =I29 -> 0.048980011 | J12: =J29 -> 0.043980011 | K12: =K29 -> 0.038980011 | L12: =L29 -> 0.033980011 | M12: =M29 -> 0.028980011 | N12: =N29 -> 0.023980011 | O12: =O29 -> 0.018980011 | P12: =P29 -> 0.013980011 | ... R12: =R29 -> 0.0039800107
C14: U.S Government | E14: 826300 | F14: 921200 | G14: 1200000 | H14: 1900000 | I14: =H14*(1+I15) -> 2533859.9 | J14: =I14*(1+J15) -> 3303166.2 | K14: =J14*(1+K15) -> 4206947.1 | L14: =K14*(1+L15) -> 5231803.4 | M14: =L14*(1+M15) -> 6349371.3 | N14: =M14*(1+N15) -> 7515182.3 | O14: =N14*(1+O15) -> 8669592.9 | P14: =O14*(1+P15) -> 9741245.3 | ... R14: =Q14*(1+R15) -> 11330778
C15: U.S Government Growth % | F15: =F14/E14-1 -> 0.11484933 | G15: =G14/F14-1 -> 0.30264872 | H15: =H14/G14-1 -> 0.58333333 | I15: =I30 -> 0.33361046 | J15: =J30 -> 0.30361046 | K15: =K30 -> 0.27361046 | L15: =L30 -> 0.24361046 | M15: =M30 -> 0.21361046 | N15: =N30 -> 0.18361046 | O15: =O30 -> 0.15361046 | P15: =P30 -> 0.12361046 | ... R15: =R30 -> 0.06361046
C17: International Government | E17: 245476 | F17: 301015 | G17: 369605 | H17: 502287 | I17: =H17*(1+I18) -> 638422.83 | J17: =I17*(1+J18) -> 798687.36 | K17: =J17*(1+K18) -> 983209.66 | L17: =K17*(1+L18) -> 1190698.3 | M17: =L17*(1+M18) -> 1418159.7 | N17: =M17*(1+N18) -> 1660710.4 | O17: =N17*(1+O18) -> 1911530.7 | P17: =O17*(1+P18) -> 2162002.3 | ... R17: =Q17*(1+R18) -> 2620717.3
C18: International Government Growth % | F18: =F17/E17-1 -> 0.22625022 | G18: =G17/F17-1 -> 0.2278624 | H18: =H17/G17-1 -> 0.35898324 | I18: =I31 -> 0.27103195 | J18: =J31 -> 0.25103195 | K18: =K31 -> 0.23103195 | L18: =L31 -> 0.21103195 | M18: =M31 -> 0.19103195 | N18: =N31 -> 0.17103195 | O18: =O31 -> 0.15103195 | P18: =P31 -> 0.13103195 | ... R18: =R31 -> 0.091031954
C20: Total Revenue | D20: 1541889 | E20: =SUM(E8,E11,E14,E17) -> 1905871 | F20: =SUM(F8,F11,F14,F17) -> 2225012 | G20: =SUM(G8,G11,G14,G17) -> 2865507 | H20: =SUM(H8,H11,H14,H17) -> 4475446 | I20: =SUM(I8,I11,I14,I17) -> 6291682.6 | J20: =SUM(J8,J11,J14,J17) -> 8831065 | K20: =SUM(K8,K11,K14,K17) -> 12317716 | L20: =SUM(L8,L11,L14,L17) -> 16996281 | ... R20: =SUM(R8,R11,R14,R17) -> 74908933
C21: Total Revenue Growth % | E21: =E20/D20-1 -> 0.23606239 | F21: =F20/E20-1 -> 0.16745152 | G21: =G20/F20-1 -> 0.28786137 | H21: =H20/G20-1 -> 0.56183391 | I21: =I20/H20-1 -> 0.40582248 | J21: =J20/I20-1 -> 0.40360942 | K21: =K20/J20-1 -> 0.39481656 | L21: =L20/K20-1 -> 0.37982412 | ... R21: =R20/Q20-1 -> 0.19283929
B24: x | C24: Scenario Analysis
H25: Variance From | I25: 2026 | J25: 2027 | K25: 2028 | L25: 2029 | M25: 2030 | N25: 2031 | O25: 2032 | P25: 2033 | Q25: 2034 | R25: 2035
C26: Active Case: | D26: =Dashboard!I8 -> Base | H26: Base Case | I26: =I6 -> 46387 | J26: =EOMONTH(I26,12) -> 46752 | K26: =EOMONTH(J26,12) -> 47118 | L26: =EOMONTH(K26,12) -> 47483 | M26: =EOMONTH(L26,12) -> 47848 | N26: =EOMONTH(M26,12) -> 48213 | O26: =EOMONTH(N26,12) -> 48579 | P26: =EOMONTH(O26,12) -> 48944 | Q26: =EOMONTH(P26,12) -> 49309 | R26: =EOMONTH(Q26,12) -> 49674
C28: U.S Commercial Growth % | H28: =OFFSET(H$39,MATCH($C28,$C$39:$C$82,0)+MATCH($D$26,$C$40:$C$42,0)-1,0) -> NM | I28: =OFFSET(I$39,MATCH($C28,$C$39:$C$82,0)+MATCH($D$26,$C$40:$C$42,0)-1,0) -> 0.67877837 | J28: =OFFSET(J$39,MATCH($C28,$C$39:$C$82,0)+MATCH($D$26,$C$40:$C$42,0)-1,0) -> 0.62877837 | K28: =OFFSET(K$39,MATCH($C28,$C$39:$C$82,0)+MATCH($D$26,$C$40:$C$42,0)-1,0) -> 0.57877837 | L28: =OFFSET(L$39,MATCH($C28,$C$39:$C$82,0)+MATCH($D$26,$C$40:$C$42,0)-1,0) -> 0.52877837 | M28: =OFFSET(M$39,MATCH($C28,$C$39:$C$82,0)+MATCH($D$26,$C$40:$C$42,0)-1,0) -> 0.47877837 | N28: =OFFSET(N$39,MATCH($C28,$C$39:$C$82,0)+MATCH($D$26,$C$40:$C$42,0)-1,0) -> 0.42877837 | O28: =OFFSET(O$39,MATCH($C28,$C$39:$C$82,0)+MATCH($D$26,$C$40:$C$42,0)-1,0) -> 0.37877837 | ... R28: =OFFSET(R$39,MATCH($C28,$C$39:$C$82,0)+MATCH($D$26,$C$40:$C$42,0)-1,0) -> 0.22877837
C29: International Commercial Growth % | H29: =OFFSET(H$39,MATCH($C29,$C$39:$C$82,0)+MATCH($D$26,$C$40:$C$42,0)-1,0) -> NM | I29: =OFFSET(I$39,MATCH($C29,$C$39:$C$82,0)+MATCH($D$26,$C$40:$C$42,0)-1,0) -> 0.048980011 | J29: =OFFSET(J$39,MATCH($C29,$C$39:$C$82,0)+MATCH($D$26,$C$40:$C$42,0)-1,0) -> 0.043980011 | K29: =OFFSET(K$39,MATCH($C29,$C$39:$C$82,0)+MATCH($D$26,$C$40:$C$42,0)-1,0) -> 0.038980011 | L29: =OFFSET(L$39,MATCH($C29,$C$39:$C$82,0)+MATCH($D$26,$C$40:$C$42,0)-1,0) -> 0.033980011 | M29: =OFFSET(M$39,MATCH($C29,$C$39:$C$82,0)+MATCH($D$26,$C$40:$C$42,0)-1,0) -> 0.028980011 | N29: =OFFSET(N$39,MATCH($C29,$C$39:$C$82,0)+MATCH($D$26,$C$40:$C$42,0)-1,0) -> 0.023980011 | O29: =OFFSET(O$39,MATCH($C29,$C$39:$C$82,0)+MATCH($D$26,$C$40:$C$42,0)-1,0) -> 0.018980011 | ... R29: =OFFSET(R$39,MATCH($C29,$C$39:$C$82,0)+MATCH($D$26,$C$40:$C$42,0)-1,0) -> 0.0039800107
C30: U.S Government Growth % | H30: =OFFSET(H$39,MATCH($C30,$C$39:$C$82,0)+MATCH($D$26,$C$40:$C$42,0)-1,0) -> NM | I30: =OFFSET(I$39,MATCH($C30,$C$39:$C$82,0)+MATCH($D$26,$C$40:$C$42,0)-1,0) -> 0.33361046 | J30: =OFFSET(J$39,MATCH($C30,$C$39:$C$82,0)+MATCH($D$26,$C$40:$C$42,0)-1,0) -> 0.30361046 | K30: =OFFSET(K$39,MATCH($C30,$C$39:$C$82,0)+MATCH($D$26,$C$40:$C$42,0)-1,0) -> 0.27361046 | L30: =OFFSET(L$39,MATCH($C30,$C$39:$C$82,0)+MATCH($D$26,$C$40:$C$42,0)-1,0) -> 0.24361046 | M30: =OFFSET(M$39,MATCH($C30,$C$39:$C$82,0)+MATCH($D$26,$C$40:$C$42,0)-1,0) -> 0.21361046 | N30: =OFFSET(N$39,MATCH($C30,$C$39:$C$82,0)+MATCH($D$26,$C$40:$C$42,0)-1,0) -> 0.18361046 | O30: =OFFSET(O$39,MATCH($C30,$C$39:$C$82,0)+MATCH($D$26,$C$40:$C$42,0)-1,0) -> 0.15361046 | ... R30: =OFFSET(R$39,MATCH($C30,$C$39:$C$82,0)+MATCH($D$26,$C$40:$C$42,0)-1,0) -> 0.06361046
C31: International Government Growth % | H31: =OFFSET(H$39,MATCH($C31,$C$39:$C$82,0)+MATCH($D$26,$C$40:$C$42,0)-1,0) -> NM | I31: =OFFSET(I$39,MATCH($C31,$C$39:$C$82,0)+MATCH($D$26,$C$40:$C$42,0)-1,0) -> 0.27103195 | J31: =OFFSET(J$39,MATCH($C31,$C$39:$C$82,0)+MATCH($D$26,$C$40:$C$42,0)-1,0) -> 0.25103195 | K31: =OFFSET(K$39,MATCH($C31,$C$39:$C$82,0)+MATCH($D$26,$C$40:$C$42,0)-1,0) -> 0.23103195 | L31: =OFFSET(L$39,MATCH($C31,$C$39:$C$82,0)+MATCH($D$26,$C$40:$C$42,0)-1,0) -> 0.21103195 | M31: =OFFSET(M$39,MATCH($C31,$C$39:$C$82,0)+MATCH($D$26,$C$40:$C$42,0)-1,0) -> 0.19103195 | N31: =OFFSET(N$39,MATCH($C31,$C$39:$C$82,0)+MATCH($D$26,$C$40:$C$42,0)-1,0) -> 0.17103195 | O31: =OFFSET(O$39,MATCH($C31,$C$39:$C$82,0)+MATCH($D$26,$C$40:$C$42,0)-1,0) -> 0.15103195 | ... R31: =OFFSET(R$39,MATCH($C31,$C$39:$C$82,0)+MATCH($D$26,$C$40:$C$42,0)-1,0) -> 0.091031954
C33: Gross margin % | H33: =OFFSET(H$39,MATCH($C33,$C$39:$C$82,0)+MATCH($D$26,$C$40:$C$42,0)-1,0) -> NM | I33: =OFFSET(I$39,MATCH($C33,$C$39:$C$82,0)+MATCH($D$26,$C$40:$C$42,0)-1,0) -> 0.82366517 | J33: =OFFSET(J$39,MATCH($C33,$C$39:$C$82,0)+MATCH($D$26,$C$40:$C$42,0)-1,0) -> 0.82366517 | K33: =OFFSET(K$39,MATCH($C33,$C$39:$C$82,0)+MATCH($D$26,$C$40:$C$42,0)-1,0) -> 0.82366517 | L33: =OFFSET(L$39,MATCH($C33,$C$39:$C$82,0)+MATCH($D$26,$C$40:$C$42,0)-1,0) -> 0.82366517 | M33: =OFFSET(M$39,MATCH($C33,$C$39:$C$82,0)+MATCH($D$26,$C$40:$C$42,0)-1,0) -> 0.82366517 | N33: =OFFSET(N$39,MATCH($C33,$C$39:$C$82,0)+MATCH($D$26,$C$40:$C$42,0)-1,0) -> 0.82366517 | O33: =OFFSET(O$39,MATCH($C33,$C$39:$C$82,0)+MATCH($D$26,$C$40:$C$42,0)-1,0) -> 0.82366517 | ... R33: =OFFSET(R$39,MATCH($C33,$C$39:$C$82,0)+MATCH($D$26,$C$40:$C$42,0)-1,0) -> 0.82366517
C34: Sales & marketing % of sales | H34: =OFFSET(H$39,MATCH($C34,$C$39:$C$82,0)+MATCH($D$26,$C$40:$C$42,0)-1,0) -> NM | I34: =OFFSET(I$39,MATCH($C34,$C$39:$C$82,0)+MATCH($D$26,$C$40:$C$42,0)-1,0) -> 0.23614607 | J34: =OFFSET(J$39,MATCH($C34,$C$39:$C$82,0)+MATCH($D$26,$C$40:$C$42,0)-1,0) -> 0.23114607 | K34: =OFFSET(K$39,MATCH($C34,$C$39:$C$82,0)+MATCH($D$26,$C$40:$C$42,0)-1,0) -> 0.22614607 | L34: =OFFSET(L$39,MATCH($C34,$C$39:$C$82,0)+MATCH($D$26,$C$40:$C$42,0)-1,0) -> 0.22114607 | M34: =OFFSET(M$39,MATCH($C34,$C$39:$C$82,0)+MATCH($D$26,$C$40:$C$42,0)-1,0) -> 0.21614607 | N34: =OFFSET(N$39,MATCH($C34,$C$39:$C$82,0)+MATCH($D$26,$C$40:$C$42,0)-1,0) -> 0.21114607 | O34: =OFFSET(O$39,MATCH($C34,$C$39:$C$82,0)+MATCH($D$26,$C$40:$C$42,0)-1,0) -> 0.20614607 | ... R34: =OFFSET(R$39,MATCH($C34,$C$39:$C$82,0)+MATCH($D$26,$C$40:$C$42,0)-1,0) -> 0.19114607
C35: Research & development % of sales | H35: =OFFSET(H$39,MATCH($C35,$C$39:$C$82,0)+MATCH($D$26,$C$40:$C$42,0)-1,0) -> NM | I35: =OFFSET(I$39,MATCH($C35,$C$39:$C$82,0)+MATCH($D$26,$C$40:$C$42,0)-1,0) -> 0.12460814 | J35: =OFFSET(J$39,MATCH($C35,$C$39:$C$82,0)+MATCH($D$26,$C$40:$C$42,0)-1,0) -> 0.11960814 | K35: =OFFSET(K$39,MATCH($C35,$C$39:$C$82,0)+MATCH($D$26,$C$40:$C$42,0)-1,0) -> 0.11460814 | L35: =OFFSET(L$39,MATCH($C35,$C$39:$C$82,0)+MATCH($D$26,$C$40:$C$42,0)-1,0) -> 0.10960814 | M35: =OFFSET(M$39,MATCH($C35,$C$39:$C$82,0)+MATCH($D$26,$C$40:$C$42,0)-1,0) -> 0.10460814 | N35: =OFFSET(N$39,MATCH($C35,$C$39:$C$82,0)+MATCH($D$26,$C$40:$C$42,0)-1,0) -> 0.09960814 | O35: =OFFSET(O$39,MATCH($C35,$C$39:$C$82,0)+MATCH($D$26,$C$40:$C$42,0)-1,0) -> 0.09460814 | ... R35: =OFFSET(R$39,MATCH($C35,$C$39:$C$82,0)+MATCH($D$26,$C$40:$C$42,0)-1,0) -> 0.07960814
C36: General & administrative % of sales | H36: =OFFSET(H$39,MATCH($C36,$C$39:$C$82,0)+MATCH($D$26,$C$40:$C$42,0)-1,0) -> NM | I36: =OFFSET(I$39,MATCH($C36,$C$39:$C$82,0)+MATCH($D$26,$C$40:$C$42,0)-1,0) -> 0.14696144 | J36: =OFFSET(J$39,MATCH($C36,$C$39:$C$82,0)+MATCH($D$26,$C$40:$C$42,0)-1,0) -> 0.14196144 | K36: =OFFSET(K$39,MATCH($C36,$C$39:$C$82,0)+MATCH($D$26,$C$40:$C$42,0)-1,0) -> 0.13696144 | L36: =OFFSET(L$39,MATCH($C36,$C$39:$C$82,0)+MATCH($D$26,$C$40:$C$42,0)-1,0) -> 0.13196144 | M36: =OFFSET(M$39,MATCH($C36,$C$39:$C$82,0)+MATCH($D$26,$C$40:$C$42,0)-1,0) -> 0.12696144 | N36: =OFFSET(N$39,MATCH($C36,$C$39:$C$82,0)+MATCH($D$26,$C$40:$C$42,0)-1,0) -> 0.12196144 | O36: =OFFSET(O$39,MATCH($C36,$C$39:$C$82,0)+MATCH($D$26,$C$40:$C$42,0)-1,0) -> 0.11696144 | ... R36: =OFFSET(R$39,MATCH($C36,$C$39:$C$82,0)+MATCH($D$26,$C$40:$C$42,0)-1,0) -> 0.10196144
C37: Other income % of sales | H37: =OFFSET(H$39,MATCH($C37,$C$39:$C$82,0)+MATCH($D$26,$C$40:$C$42,0)-1,0) -> NM | I37: =OFFSET(I$39,MATCH($C37,$C$39:$C$82,0)+MATCH($D$26,$C$40:$C$42,0)-1,0) -> 0.0031666118 | J37: =OFFSET(J$39,MATCH($C37,$C$39:$C$82,0)+MATCH($D$26,$C$40:$C$42,0)-1,0) -> 0.0031666118 | K37: =OFFSET(K$39,MATCH($C37,$C$39:$C$82,0)+MATCH($D$26,$C$40:$C$42,0)-1,0) -> 0.0031666118 | L37: =OFFSET(L$39,MATCH($C37,$C$39:$C$82,0)+MATCH($D$26,$C$40:$C$42,0)-1,0) -> 0.0031666118 | M37: =OFFSET(M$39,MATCH($C37,$C$39:$C$82,0)+MATCH($D$26,$C$40:$C$42,0)-1,0) -> 0.0031666118 | N37: =OFFSET(N$39,MATCH($C37,$C$39:$C$82,0)+MATCH($D$26,$C$40:$C$42,0)-1,0) -> 0.0031666118 | O37: =OFFSET(O$39,MATCH($C37,$C$39:$C$82,0)+MATCH($D$26,$C$40:$C$42,0)-1,0) -> 0.0031666118 | ... R37: =OFFSET(R$39,MATCH($C37,$C$39:$C$82,0)+MATCH($D$26,$C$40:$C$42,0)-1,0) -> 0.0031666118
C39: U.S Commercial Growth %
C40: Bull | H40: 0.02 | I40: =I41+$H$40 -> 0.69877837 | J40: =J41+$H$40 -> 0.64877837 | K40: =K41+$H$40 -> 0.59877837 | L40: =L41+$H$40 -> 0.54877837 | M40: =M41+$H$40 -> 0.49877837 | N40: =N41+$H$40 -> 0.44877837 | O40: =O41+$H$40 -> 0.39877837 | P40: =P41+$H$40 -> 0.34877837 | ... R40: =R41+$H$40 -> 0.24877837 | T40: Step
C41: Base | H41: NM | I41: =AVERAGE(F9:H9) -> 0.67877837 | J41: =I41+$T$41 -> 0.62877837 | K41: =J41+$T$41 -> 0.57877837 | L41: =K41+$T$41 -> 0.52877837 | M41: =L41+$T$41 -> 0.47877837 | N41: =M41+$T$41 -> 0.42877837 | O41: =N41+$T$41 -> 0.37877837 | P41: =O41+$T$41 -> 0.32877837 | Q41: =P41+$T$41 -> 0.27877837 | R41: =Q41+$T$41 -> 0.22877837 | T41: -0.05
C42: Bear | H42: -0.02 | I42: =I41+$H$42 -> 0.65877837 | J42: =J41+$H$42 -> 0.60877837 | K42: =K41+$H$42 -> 0.55877837 | L42: =L41+$H$42 -> 0.50877837 | M42: =M41+$H$42 -> 0.45877837 | N42: =N41+$H$42 -> 0.40877837 | O42: =O41+$H$42 -> 0.35877837 | P42: =P41+$H$42 -> 0.30877837 | ... R42: =R41+$H$42 -> 0.20877837
C44: International Commercial Growth %
C45: Bull | H45: 0.01 | I45: =I46+$H$45 -> 0.058980011 | J45: =J46+$H$45 -> 0.053980011 | K45: =K46+$H$45 -> 0.048980011 | L45: =L46+$H$45 -> 0.043980011 | M45: =M46+$H$45 -> 0.038980011 | N45: =N46+$H$45 -> 0.033980011 | O45: =O46+$H$45 -> 0.028980011 | P45: =P46+$H$45 -> 0.023980011 | ... R45: =R46+$H$45 -> 0.013980011 | T45: Step
C46: Base | H46: NM | I46: =AVERAGE(F12:H12) -> 0.048980011 | J46: =I46+$T$46 -> 0.043980011 | K46: =J46+$T$46 -> 0.038980011 | L46: =K46+$T$46 -> 0.033980011 | M46: =L46+$T$46 -> 0.028980011 | N46: =M46+$T$46 -> 0.023980011 | O46: =N46+$T$46 -> 0.018980011 | P46: =O46+$T$46 -> 0.013980011 | Q46: =P46+$T$46 -> 0.0089800107 | R46: =Q46+$T$46 -> 0.0039800107 | T46: -0.005
C47: Bear | H47: -0.01 | I47: =I46+$H$47 -> 0.038980011 | J47: =J46+$H$47 -> 0.033980011 | K47: =K46+$H$47 -> 0.028980011 | L47: =L46+$H$47 -> 0.023980011 | M47: =M46+$H$47 -> 0.018980011 | N47: =N46+$H$47 -> 0.013980011 | O47: =O46+$H$47 -> 0.0089800107 | P47: =P46+$H$47 -> 0.0039800107 | ... R47: =R46+$H$47 -> -0.0060199893
C49: U.S Government Growth %
C50: Bull | H50: 0.02 | I50: =I51+$H$50 -> 0.35361046 | J50: =J51+$H$50 -> 0.32361046 | K50: =K51+$H$50 -> 0.29361046 | L50: =L51+$H$50 -> 0.26361046 | M50: =M51+$H$50 -> 0.23361046 | N50: =N51+$H$50 -> 0.20361046 | O50: =O51+$H$50 -> 0.17361046 | P50: =P51+$H$50 -> 0.14361046 | ... R50: =R51+$H$50 -> 0.08361046 | T50: Step
C51: Base | H51: NM | I51: =AVERAGE(F15:H15) -> 0.33361046 | J51: =I51+$T$51 -> 0.30361046 | K51: =J51+$T$51 -> 0.27361046 | L51: =K51+$T$51 -> 0.24361046 | M51: =L51+$T$51 -> 0.21361046 | N51: =M51+$T$51 -> 0.18361046 | O51: =N51+$T$51 -> 0.15361046 | P51: =O51+$T$51 -> 0.12361046 | Q51: =P51+$T$51 -> 0.09361046 | R51: =Q51+$T$51 -> 0.06361046 | T51: -0.03
C52: Bear | H52: -0.02 | I52: =I51+$H$52 -> 0.31361046 | J52: =J51+$H$52 -> 0.28361046 | K52: =K51+$H$52 -> 0.25361046 | L52: =L51+$H$52 -> 0.22361046 | M52: =M51+$H$52 -> 0.19361046 | N52: =N51+$H$52 -> 0.16361046 | O52: =O51+$H$52 -> 0.13361046 | P52: =P51+$H$52 -> 0.10361046 | ... R52: =R51+$H$52 -> 0.04361046
C54: International Government Growth %
C55: Bull | H55: 0.02 | I55: =I56+$H$55 -> 0.29103195 | J55: =J56+$H$55 -> 0.27103195 | K55: =K56+$H$55 -> 0.25103195 | L55: =L56+$H$55 -> 0.23103195 | M55: =M56+$H$55 -> 0.21103195 | N55: =N56+$H$55 -> 0.19103195 | O55: =O56+$H$55 -> 0.17103195 | P55: =P56+$H$55 -> 0.15103195 | ... R55: =R56+$H$55 -> 0.11103195 | T55: Step
...

Sheet FSM
C2: Financial Statement Model
C3: $USD Thousand except per share data
C5: Circ Break 1 = off, 0 = on | D5: 1
C6: Latest Fiscal Year End Date | D6: 46022
C7: Shares Outstanding (thousands) | D7: 2391675.7
B9: x | C9: INCOME STATEMENT
C10: Fiscal Year | D10: 2021 | E10: 2022 | F10: 2023 | G10: 2024 | H10: 2025 | I10: 2026 | J10: 2027 | K10: 2028 | L10: 2029 | M10: 2030 | N10: 2031 | O10: 2032 | P10: 2033 | Q10: 2034 | R10: 2035
C11: End Date | D11: 44561 | E11: =EOMONTH(D11,12) -> 44926 | F11: =EOMONTH(E11,12) -> 45291 | G11: =EOMONTH(F11,12) -> 45657 | H11: =EOMONTH(G11,12) -> 46022 | I11: =EOMONTH(H11,12) -> 46387 | J11: =EOMONTH(I11,12) -> 46752 | K11: =EOMONTH(J11,12) -> 47118 | L11: =EOMONTH(K11,12) -> 47483 | ... R11: =EOMONTH(Q11,12) -> 49674
C13: Revenue | D13: 1541889 | E13: 1905871 | F13: 2225012 | G13: 2865507 | H13: 4475446 | I13: ='Rev Build'!I20 -> 6291682.6 | J13: ='Rev Build'!J20 -> 8831065 | K13: ='Rev Build'!K20 -> 12317716 | L13: ='Rev Build'!L20 -> 16996281 | M13: ='Rev Build'!M20 -> 23100508 | N13: ='Rev Build'!N20 -> 30802452 | O13: ='Rev Build'!O20 -> 40143726 | P13: ='Rev Build'!P20 -> 50957491 | ... R13: ='Rev Build'!R20 -> 74908933
C14: Cost of revenue | D14: -339404 | E14: -408549 | F14: -431105 | G14: -565990 | H14: -789177 | I14: =I15-I13 -> -1109442.8 | J14: =J15-J13 -> -1557224.3 | K14: =K15-K13 -> -2172042.3 | L14: =L15-L13 -> -2997036.3 | M14: =M15-M13 -> -4073424.1 | N14: =N15-N13 -> -5431545.1 | O14: =O15-O13 -> -7078737 | P14: =P15-P13 -> -8985580.4 | ... R14: =R15-R13 -> -13209054
C15: Gross profit | D15: =SUM(D13:D14) -> 1202485 | E15: =SUM(E13:E14) -> 1497322 | F15: =SUM(F13:F14) -> 1793907 | G15: =SUM(G13:G14) -> 2299517 | H15: =SUM(H13:H14) -> 3686269 | I15: =I13*I38 -> 5182239.8 | J15: =J13*J38 -> 7273840.6 | K15: =K13*K38 -> 10145673 | L15: =L13*L38 -> 13999245 | M15: =M13*M38 -> 19027084 | N15: =N13*N38 -> 25370907 | O15: =O13*O38 -> 33064989 | P15: =P13*P38 -> 41971911 | ... R15: =R13*R38 -> 61699879
C16: Sales and marketing | D16: -614512 | E16: -702511 | F16: -744992 | G16: -887755 | H16: -1056859 | I16: =I13*-I40 -> -1485756.1 | J16: =J13*-J40 -> -2041266 | K16: =K13*-K40 -> -2785603 | L16: =L13*-L40 -> -3758660.8 | M16: =M13*-M40 -> -4993084.1 | N16: =N13*-N40 -> -6503816.8 | O16: =O13*-O40 -> -8275471.5 | P16: =P13*-P40 -> -10249899 | ... R16: =R13*-R40 -> -14318548
C17: Research and development | D17: -387487 | E17: -359679 | F17: -404624 | G17: -507878 | H17: -557677 | I17: =I13*-I41 -> -783994.86 | J17: =J13*-J41 -> -1056267.3 | K17: =K13*-K41 -> -1411710.5 | L17: =L13*-L41 -> -1862930.8 | M17: =M13*-M41 -> -2416501.1 | N17: =N13*-N41 -> -3068174.9 | O17: =O13*-O41 -> -3797923.2 | P17: =P13*-P41 -> -4566206 | ... R17: =R13*-R41 -> -5963360.8
C18: General and administrative | D18: -611532 | E18: -596333 | F18: -524325 | G18: -593481 | H18: -657718 | I18: =I13*-I42 -> -924634.75 | J18: =J13*-J42 -> -1253670.7 | K18: =K13*-K42 -> -1687052.1 | L18: =L13*-L42 -> -2242853.8 | M18: =M13*-M42 -> -2932873.8 | N18: =N13*-N42 -> -3756711.5 | O18: =O13*-O42 -> -4695268.1 | P18: =P13*-P42 -> -5705274.2 | ... R18: =R13*-R42 -> -7637822.8
C19: Operating income (EBIT) | D19: =SUM(D15:D18) -> -411046 | E19: =SUM(E15:E18) -> -161201 | F19: =SUM(F15:F18) -> 119966 | G19: =SUM(G15:G18) -> 310403 | H19: =SUM(H15:H18) -> 1414015 | I19: =SUM(I15:I18) -> 1987854.1 | J19: =SUM(J15:J18) -> 2922636.7 | K19: =SUM(K15:K18) -> 4261307.8 | ... R19: =SUM(R15:R18) -> 33780147
C20: Interest income | D20: 1607 | E20: 20309 | F20: 132572 | G20: 196792 | H20: 229181 | I20: =I247 -> 268401.55 | J20: =J247 -> 365371.2 | K20: =K247 -> 506754.02 | L20: =L247 -> 710403.03 | M20: =M247 -> 999095.58 | N20: =N247 -> 1402492.8 | O20: =O247 -> 1953579.4 | P20: =P247 -> 2685409.1 | ... R20: =R247 -> 4816021.1
C21: Other income (expense), net | D21: =-75415-3640 -> -79055 | E21: =-216077-4058 -> -220135 | F21: =-11977-3470 -> -15447 | G21: -18022 | H21: 14172 | I21: =I13*I44 -> 19923.316 | J21: =J13*J44 -> 27964.554 | K21: =K13*K44 -> 39005.423 | L21: =L13*L44 -> 53820.624 | M21: =M13*M44 -> 73150.34 | N21: =N13*N44 -> 97539.407 | O21: =O13*O44 -> 127119.6 | P21: =P13*P44 -> 161362.59 | ... R21: =R13*R44 -> 237207.51
C22: Income before provision for income taxes | D22: =SUM(D19:D21) -> -488494 | E22: =SUM(E19:E21) -> -361027 | F22: =SUM(F19:F21) -> 237091 | G22: =SUM(G19:G21) -> 489173 | H22: =SUM(H19:H21) -> 1657368 | I22: =SUM(I19:I21) -> 2276178.9 | J22: =SUM(J19:J21) -> 3315972.4 | K22: =SUM(K19:K21) -> 4807067.2 | ... R22: =SUM(R19:R21) -> 38833376
C23: Provision for income taxes | D23: -31885 | E23: -10067 | F23: -19716 | G23: -21255 | H23: -22724 | I23: =I22*-I45 -> -521700.21 | J23: =J22*-J45 -> -758694.49 | K23: =K22*-K45 -> -1084955.1 | L23: =L22*-L45 -> -1517785.1 | M23: =M22*-M45 -> -2146511.5 | N23: =N22*-N45 -> -2843869.6 | O23: =O22*-O45 -> -3859175.3 | P23: =P22*-P45 -> -5102433.6 | ... R23: =R22*-R45 -> -8155008.9
C24: Net income | D24: =SUM(D22:D23) -> -520379 | E24: =SUM(E22:E23) -> -371094 | F24: =SUM(F22:F23) -> 217375 | G24: =SUM(G22:G23) -> 467918 | H24: =SUM(H22:H23) -> 1634644 | I24: =SUM(I22:I23) -> 1754478.7 | J24: =SUM(J22:J23) -> 2557277.9 | K24: =SUM(K22:K23) -> 3722112.1 | ... R24: =SUM(R22:R23) -> 30678367
C25: Less: Net income attributable to noncontrolling interests | D25: 0 | E25: -2611 | F25: -7550 | G25: -5728 | H25: -9611 | I25: =H25 -> -9611 | J25: =I25 -> -9611 | K25: =J25 -> -9611 | L25: =K25 -> -9611 | M25: =L25 -> -9611 | N25: =M25 -> -9611 | O25: =N25 -> -9611 | P25: =O25 -> -9611 | ... R25: =Q25 -> -9611
C26: Net income attributable to common stockholders | D26: =SUM(D24:D25) -> -520379 | E26: =SUM(E24:E25) -> -373705 | F26: =SUM(F24:F25) -> 209825 | G26: =SUM(G24:G25) -> 462190 | H26: =SUM(H24:H25) -> 1625033 | I26: =SUM(I24:I25) -> 1744867.7 | J26: =SUM(J24:J25) -> 2547666.9 | K26: =SUM(K24:K25) -> 3712501.1 | ... R26: =SUM(R24:R25) -> 30668756
C28: Basic EPS | D28: -0.27 | E28: -0.18 | F28: 0.1 | G28: 0.21 | H28: 0.69 | I28: =I266 -> 0.72879866 | J28: =J266 -> 1.0636408 | K28: =K266 -> 1.5490193 | L28: =L266 -> 2.2394824 | M28: =M266 -> 3.1655402 | N28: =N266 -> 4.4458652 | O28: =O266 -> 6.0251609 | P28: =P266 -> 7.9533215 | ... R28: =R266 -> 12.664744
C29: Diluted EPS | D29: -0.27 | E29: -0.18 | F29: 0.09 | G29: 0.19 | H29: 0.63 | I29: =I269 -> 0.67375789 | J29: =J269 -> 0.98334487 | K29: =K269 -> 1.4321465 | L29: =L269 -> 2.0706399 | M29: =M269 -> 2.9271076 | N29: =N269 -> 4.1113975 | O29: =O269 -> 5.5725322 | P29: =P269 -> 7.3568263 | ... R29: =R269 -> 11.718289
C31: Depreciation and amortization | D31: 14897 | E31: 22522 | F31: 33354 | G31: 31587 | H31: 26145 | I31: =I210 -> 25239.136 | J31: =J210 -> 33966.268 | K31: =K210 -> 48413.422 | L31: =L210 -> 69840.69 | M31: =M210 -> 99829.69 | N31: =N210 -> 140141.99 | O31: =O210 -> 192491.29 | P31: =P210 -> 257089.08 | ... R31: =R210 -> 414205.03
C32: EBITDA | D32: =D19+D31 -> -396149 | E32: =E19+E31 -> -138679 | F32: =F19+F31 -> 153320 | G32: =G19+G31 -> 341990 | H32: =H19+H31 -> 1440160 | I32: =I19+I31 -> 2013093.2 | J32: =J19+J31 -> 2956602.9 | K32: =K19+K31 -> 4309721.2 | ... R32: =R19+R31 -> 34194352
C33: Stock-based compensation | D33: 778215 | E33: 564798 | F33: 475903 | G33: 691638 | H33: 684033 | I33: =H33*(1+I37) -> 961628.97 | J33: =I33*(1+J37) -> 1349751.5 | K33: =J33*(1+K37) -> 1882655.7 | L33: =K33*(1+L37) -> 2597733.8 | M33: =L33*(1+M37) -> 3530711.7 | N33: =M33*(1+N37) -> 4707886.9 | O33: =N33*(1+O37) -> 6135619.4 | P33: =O33*(1+P37) -> 7788409.3 | ... R33: =Q33*(1+R37) -> 11449179
C34: Adjusted EBITDA | D34: =D32+D33 -> 382066 | E34: =E32+E33 -> 426119 | F34: =F32+F33 -> 629223 | G34: =G32+G33 -> 1033628 | H34: =H32+H33 -> 2124193 | I34: =I32+I33 -> 2974722.2 | J34: =J32+J33 -> 4306354.4 | K34: =K32+K33 -> 6192376.9 | ... R34: =R32+R33 -> 45643531
C36: Growth rates and margins
C37: Revenue growth % | E37: ='Rev Build'!E21 -> 0.23606239 | F37: ='Rev Build'!F21 -> 0.16745152 | G37: ='Rev Build'!G21 -> 0.28786137 | H37: ='Rev Build'!H21 -> 0.56183391 | I37: ='Rev Build'!I21 -> 0.40582248 | J37: ='Rev Build'!J21 -> 0.40360942 | K37: ='Rev Build'!K21 -> 0.39481656 | L37: ='Rev Build'!L21 -> 0.37982412 | ... R37: ='Rev Build'!R21 -> 0.19283929
C38: Gross margin % | D38: =D15/D13 -> 0.7798778 | E38: =E15/E13 -> 0.78563659 | F38: =F15/F13 -> 0.80624599 | G38: =G15/G13 -> 0.80248172 | H38: =H15/H13 -> 0.82366517 | I38: ='Rev Build'!I33 -> 0.82366517 | J38: ='Rev Build'!J33 -> 0.82366517 | K38: ='Rev Build'!K33 -> 0.82366517 | L38: ='Rev Build'!L33 -> 0.82366517 | M38: ='Rev Build'!M33 -> 0.82366517 | N38: ='Rev Build'!N33 -> 0.82366517 | O38: ='Rev Build'!O33 -> 0.82366517 | P38: ='Rev Build'!P33 -> 0.82366517 | ... R38: ='Rev Build'!R33 -> 0.82366517
C40: Sales & marketing % of sales | D40: =-D16/D13 -> 0.3985449 | E40: =-E16/E13 -> 0.36860365 | F40: =-F16/F13 -> 0.33482606 | G40: =-G16/G13 -> 0.3098073 | H40: =-H16/H13 -> 0.23614607 | I40: ='Rev Build'!I34 -> 0.23614607 | J40: ='Rev Build'!J34 -> 0.23114607 | K40: ='Rev Build'!K34 -> 0.22614607 | L40: ='Rev Build'!L34 -> 0.22114607 | M40: ='Rev Build'!M34 -> 0.21614607 | N40: ='Rev Build'!N34 -> 0.21114607 | O40: ='Rev Build'!O34 -> 0.20614607 | P40: ='Rev Build'!P34 -> 0.20114607 | ... R40: ='Rev Build'!R34 -> 0.19114607
C41: Research & development % of sales | D41: =-D17/D13 -> 0.25130668 | E41: =-E17/E13 -> 0.18872159 | F41: =-F17/F13 -> 0.1818525 | G41: =-G17/G13 -> 0.17723844 | H41: =-H17/H13 -> 0.12460814 | I41: ='Rev Build'!I35 -> 0.12460814 | J41: ='Rev Build'!J35 -> 0.11960814 | K41: ='Rev Build'!K35 -> 0.11460814 | L41: ='Rev Build'!L35 -> 0.10960814 | M41: ='Rev Build'!M35 -> 0.10460814 | N41: ='Rev Build'!N35 -> 0.09960814 | O41: ='Rev Build'!O35 -> 0.09460814 | P41: ='Rev Build'!P35 -> 0.08960814 | ... R41: ='Rev Build'!R35 -> 0.07960814
C42: General & administrative % of sales | D42: =-D18/D13 -> 0.39661221 | E42: =-E18/E13 -> 0.31289264 | F42: =-F18/F13 -> 0.23565041 | G42: =-G18/G13 -> 0.20711204 | H42: =-H18/H13 -> 0.14696144 | I42: ='Rev Build'!I36 -> 0.14696144 | J42: ='Rev Build'!J36 -> 0.14196144 | K42: ='Rev Build'!K36 -> 0.13696144 | L42: ='Rev Build'!L36 -> 0.13196144 | M42: ='Rev Build'!M36 -> 0.12696144 | N42: ='Rev Build'!N36 -> 0.12196144 | O42: ='Rev Build'!O36 -> 0.11696144 | P42: ='Rev Build'!P36 -> 0.11196144 | ... R42: ='Rev Build'!R36 -> 0.10196144
C44: Other income % of sales | D44: =D21/D13 -> -0.051271525 | E44: =E21/E13 -> -0.11550362 | F44: =F21/F13 -> -0.0069424345 | G44: =G21/G13 -> -0.0062892884 | H44: =H21/H13 -> 0.0031666118 | I44: ='Rev Build'!I37 -> 0.0031666118 | J44: ='Rev Build'!J37 -> 0.0031666118 | K44: ='Rev Build'!K37 -> 0.0031666118 | L44: ='Rev Build'!L37 -> 0.0031666118 | M44: ='Rev Build'!M37 -> 0.0031666118 | N44: ='Rev Build'!N37 -> 0.0031666118 | O44: ='Rev Build'!O37 -> 0.0031666118 | P44: ='Rev Build'!P37 -> 0.0031666118 | ... R44: ='Rev Build'!R37 -> 0.0031666118
C45: Effective Tax Rate | D45: =-D23/D22 -> -0.06527204 | E45: =-E23/E22 -> -0.027884341 | F45: =-F23/F22 -> 0.083157944 | G45: =-G23/G22 -> 0.043450885 | H45: =-H23/H22 -> 0.013710896 | I45: 0.2292 | J45: 0.2288 | K45: 0.2257 | L45: 0.22 | M45: 0.22 | N45: 0.21 | O45: 0.21 | P45: 0.21 | Q45: 0.21 | R45: 0.21
B48: x | C48: BALANCE SHEET
C49: Fiscal Year | D49: 2021 | E49: 2022 | F49: 2023 | G49: 2024 | H49: 2025 | I49: 2026 | J49: 2027 | K49: 2028 | L49: 2029 | M49: 2030 | N49: 2031 | O49: 2032 | P49: 2033 | Q49: 2034 | R49: 2035
C50: End Date | D50: 44561 | E50: =EOMONTH(D50,12) -> 44926 | F50: =EOMONTH(E50,12) -> 45291 | G50: =EOMONTH(F50,12) -> 45657 | H50: =EOMONTH(G50,12) -> 46022 | I50: =EOMONTH(H50,12) -> 46387 | J50: =EOMONTH(I50,12) -> 46752 | K50: =EOMONTH(J50,12) -> 47118 | L50: =EOMONTH(K50,12) -> 47483 | ... R50: =EOMONTH(Q50,12) -> 49674
C52: Cash & cash equivalents and marketable securities | D52: 2601067 | E52: 2633675 | F52: 3674179 | G52: 5229987 | H52: 7177043 | I52: =I108 -> 9633508.4 | J52: =J108 -> 13250455 | K52: =K108 -> 18488610 | L52: =L108 -> 26005419 | M52: =M108 -> 36570029 | N52: =N108 -> 51271034 | O52: =O108 -> 71085734 | P52: =P108 -> 97107060 | ... R52: =R108 -> 1.7133542e+08
...

Sheet Intrinsic>>>

Sheet WACC
C2: WACC Analysis
C3: $USD Thousand except per share data
C5: INPUTS | H5: BETA CALCULATION
J6: 5-year
C7: Tax rate (5-year average) | F7: =SUM(FSM!D45:H45)/5 -> 0.0094326687 | H7: Company Name | I7: Ticker | J7: average tax rate | K7: Levered Beta | L7: Total Debt | M7: Market cap | N7: Unlevered Beta
C8: Risk-free rate | F8: 0.04731 | H8: Datadog | I8: NASDAQ: DDOG | J8: 0.13168 | K8: 1.36 | L8: =SUM(Inputs!D79:D82) -> 1279005 | M8: =Inputs!D77 -> 47373805 | N8: =K8/(1+(1-J8)*(L8/M8)) -> 1.3288478
C9: Market risk premium | F9: 0.0446 | H9: Snowflake | I9: NYSE: SNOW | J9: 0.25646667 | K9: 1.21 | L9: =SUM(Inputs!F79:F82) -> 407866 | M9: =Inputs!F77 -> 69648794 | N9: =K9/(1+(1-J9)*(L9/M9)) -> 1.2047543
H10: Hubspot | I10: NYSE: HUBS | J10: 0.20154 | K10: 1.45 | L10: =SUM(Inputs!H79:H82) -> 262305 | M10: =Inputs!H77 -> 13966518 | N10: =K10/(1+(1-J10)*(L10/M10)) -> 1.4285772
C11: WACC | H11: Salesforce | I11: NYSE: CRM | J11: 0.22202 | K11: 1.31 | L11: =SUM(Inputs!J79:J82) -> 17176000 | M11: =Inputs!J77 -> 188319600 | N11: =K11/(1+(1-J11)*(L11/M11)) -> 1.2232051
H12: Oracle | I12: NYSE: ORCL | J12: 0.1748 | K12: 1.65 | L12: =SUM(Inputs!L79:L82) -> 161425000 | M12: =Inputs!L77 -> 4.8122046e+08 | N12: =K12/(1+(1-J12)*(L12/M12)) -> 1.2922804
C13: Market risk premium | F13: =F9 -> 0.0446 | H13: Palo Alto Networks | I13: NASDAQ: PANW | J13: 0.21998 | K13: 0.82 | L13: =SUM(Inputs!N79:N82) -> 372000 | M13: =Inputs!N77 -> 140892940 | N13: =K13/(1+(1-J13)*(L13/M13)) -> 0.81831469
C14: Levered Beta | F14: =N18 -> 1.2170015 | H14: Average | N14: =AVERAGE(N8:N13) -> 1.2159966
C15: Adjusted market risk premium | F15: =F13*F14 -> 0.054278268 | H15: Palantir Avg tax rate | N15: =F7 -> 0.0094326687
C16: Add: risk-free rate | F16: =F8 -> 0.04731 | H16: Total Debt | N16: =SUM(DCF!N55:N56) -> 330081
C17: Cost of Equity | F17: =F15+F16 -> 0.10158827 | H17: Market cap | N17: =DCF!S60*DCF!D8 -> 3.9564159e+08
C18: Equity to total capitalization | F18: 1 | H18: PLTR Levered Beta | N18: =N14*(1+(1-F7)*(N16/N17)) -> 1.2170015
C19: Cost of equity portion | F19: =F17*F18 -> 0.10158827
H20: WACC Sensitivity
C21: Cost of debt | F21: 0
C22: Tax rate | F22: =F7 -> 0.0094326687 | H22: Pre-tax cost of debt
C23: After-tax cost of debt | F23: =F21*F22 -> 0 | H23: =F27 -> 0.10158827 | I23: 0.01 | J23: =I23+$P$25 -> 0.02 | K23: =J23+$P$25 -> 0.03 | L23: =K23+$P$25 -> 0.04 | M23: =L23+$P$25 -> 0.05 | N23: =M23+$P$25 -> 0.06
C24: Debt to total capitalization | F24: 0 | H24: 0.05 | I24: 0.10159298 | J24: 0.1015977 | K24: 0.10160242 | L24: 0.10160713 | M24: 0.10161185 | N24: 0.10161657
C25: Cost of debt portion | F25: =F23*F24 -> 0 | H25: =H24+$P$26 -> 0.1 | I25: 0.1015977 | J25: 0.10160713 | K25: 0.10161657 | L25: 0.101626 | M25: 0.10163543 | N25: 0.10164486 | P25: 0.01 | Q25: Pre-tax cost of debt step
H26: =H25+$P$26 -> 0.15 | I26: 0.10160242 | J26: 0.10161657 | K26: 0.10163071 | L26: 0.10164486 | M26: 0.10165901 | N26: 0.10167316 | P26: 0.05 | Q26: Debt to total cap/Equity to total cap step
C27: WACC | F27: =F19+F25 -> 0.10158827 | H27: =H26+$P$26 -> 0.2 | I27: 0.10160713 | J27: 0.101626 | K27: 0.10164486 | L27: 0.10166373 | M27: 0.10168259 | N27: 0.10170146 | P27: 0.02 | Q27: Cost of equity step
H28: =H27+$P$26 -> 0.25 | I28: 0.10161185 | J28: 0.10163543 | K28: 0.10165901 | L28: 0.10168259 | M28: 0.10170618 | N28: 0.10172976
H29: =H28+$P$26 -> 0.3 | I29: 0.10161657 | J29: 0.10164486 | K29: 0.10167316 | L29: 0.10170146 | M29: 0.10172976 | N29: 0.10175806
H31: Cost of Equity
H32: =F27 -> 0.10158827 | I32: 0.06 | J32: =I32+$P$27 -> 0.08 | K32: =J32+$P$27 -> 0.1 | L32: =K32+$P$27 -> 0.12 | M32: =L32+$P$27 -> 0.14 | N32: =M32+$P$27 -> 0.16
H33: 0.6 | I33: 0.036 | J33: 0.048 | K33: 0.06 | L33: 0.072 | M33: 0.084 | N33: 0.096
H34: =H33+$P$26 -> 0.65 | I34: 0.039 | J34: 0.052 | K34: 0.065 | L34: 0.078 | M34: 0.091 | N34: 0.104
H35: =H34+$P$26 -> 0.7 | I35: 0.042 | J35: 0.056 | K35: 0.07 | L35: 0.084 | M35: 0.098 | N35: 0.112
H36: =H35+$P$26 -> 0.75 | I36: 0.045 | J36: 0.06 | K36: 0.075 | L36: 0.09 | M36: 0.105 | N36: 0.12
H37: =H36+$P$26 -> 0.8 | I37: 0.048 | J37: 0.064 | K37: 0.08 | L37: 0.096 | M37: 0.112 | N37: 0.128
H38: =H37+$P$26 -> 0.85 | I38: 0.051 | J38: 0.068 | K38: 0.085 | L38: 0.102 | M38: 0.119 | N38: 0.136

Sheet DCF
C2: Discounted Cash Flows
C3: $USD Thousand except per share data
C5: Most recent fiscal year end | D5: 46022 | I5: Discount rate (WACC) | K5: =WACC!F27 -> 0.10158827
C6: End of first fiscal year | D6: 46387 | I6: Midyear convention | K6: 1
C7: Valuation date | D7: 46093
C8: Share price | D8: =Dashboard!D10 -> 153.5
C9: Share price date | D9: 46093 | I9: Active Case: | K9: =Dashboard!I8 -> Base
C10: Potion of first year cash flows | D10: =YEARFRAC(D7,D6) -> 0.80277778
B12: x | C12: Fiscal Year | J12: 2026 | K12: 2027 | L12: 2028 | M12: 2029 | N12: 2030 | O12: 2031 | P12: 2032 | Q12: 2033 | R12: 2034 | S12: 2035
C13: End Date | J13: 46387 | K13: =EOMONTH(J13,12) -> 46752 | L13: =EOMONTH(K13,12) -> 47118 | M13: =EOMONTH(L13,12) -> 47483 | N13: =EOMONTH(M13,12) -> 47848 | O13: =EOMONTH(N13,12) -> 48213 | P13: =EOMONTH(O13,12) -> 48579 | Q13: =EOMONTH(P13,12) -> 48944 | R13: =EOMONTH(Q13,12) -> 49309 | S13: =EOMONTH(R13,12) -> 49674
C15: Revenue | J15: =FSM!I13 -> 6291682.6 | K15: =FSM!J13 -> 8831065 | L15: =FSM!K13 -> 12317716 | M15: =FSM!L13 -> 16996281 | N15: =FSM!M13 -> 23100508 | O15: =FSM!N13 -> 30802452 | P15: =FSM!O13 -> 40143726 | Q15: =FSM!P13 -> 50957491 | ... S15: =FSM!R13 -> 74908933
C16: Cost of revenue | J16: =FSM!I14 -> -1109442.8 | K16: =FSM!J14 -> -1557224.3 | L16: =FSM!K14 -> -2172042.3 | M16: =FSM!L14 -> -2997036.3 | N16: =FSM!M14 -> -4073424.1 | O16: =FSM!N14 -> -5431545.1 | P16: =FSM!O14 -> -7078737 | Q16: =FSM!P14 -> -8985580.4 | ... S16: =FSM!R14 -> -13209054
C17: Gross profit | J17: =J15+J16 -> 5182239.8 | K17: =K15+K16 -> 7273840.6 | L17: =L15+L16 -> 10145673 | M17: =M15+M16 -> 13999245 | N17: =N15+N16 -> 19027084 | O17: =O15+O16 -> 25370907 | P17: =P15+P16 -> 33064989 | Q17: =Q15+Q16 -> 41971911 | ... S17: =S15+S16 -> 61699879
C18: Operating expenses
C19: Sales and marketing | J19: =FSM!I16 -> -1485756.1 | K19: =FSM!J16 -> -2041266 | L19: =FSM!K16 -> -2785603 | M19: =FSM!L16 -> -3758660.8 | N19: =FSM!M16 -> -4993084.1 | O19: =FSM!N16 -> -6503816.8 | P19: =FSM!O16 -> -8275471.5 | Q19: =FSM!P16 -> -10249899 | ... S19: =FSM!R16 -> -14318548
C20: Research and development | J20: =FSM!I17 -> -783994.86 | K20: =FSM!J17 -> -1056267.3 | L20: =FSM!K17 -> -1411710.5 | M20: =FSM!L17 -> -1862930.8 | N20: =FSM!M17 -> -2416501.1 | O20: =FSM!N17 -> -3068174.9 | P20: =FSM!O17 -> -3797923.2 | Q20: =FSM!P17 -> -4566206 | ... S20: =FSM!R17 -> -5963360.8
C21: General and administrative | J21: =FSM!I18 -> -924634.75 | K21: =FSM!J18 -> -1253670.7 | L21: =FSM!K18 -> -1687052.1 | M21: =FSM!L18 -> -2242853.8 | N21: =FSM!M18 -> -2932873.8 | O21: =FSM!N18 -> -3756711.5 | P21: =FSM!O18 -> -4695268.1 | Q21: =FSM!P18 -> -5705274.2 | ... S21: =FSM!R18 -> -7637822.8
C22: Operating income | J22: =J17+SUM(J19:J21) -> 1987854.1 | K22: =K17+SUM(K19:K21) -> 2922636.7 | L22: =L17+SUM(L19:L21) -> 4261307.8 | M22: =M17+SUM(M19:M21) -> 6134799.5 | N22: =N17+SUM(N19:N21) -> 8684624.8 | O22: =O17+SUM(O19:O21) -> 12042204 | P22: =P17+SUM(P19:P21) -> 16296326 | Q22: =Q17+SUM(Q19:Q21) -> 21450531 | ... S22: =S17+SUM(S19:S21) -> 33780147
C23: Tax expense | J23: =J22*-FSM!I45 -> -455616.15 | K23: =K22*-FSM!J45 -> -668699.27 | L23: =L22*-FSM!K45 -> -961777.16 | M23: =M22*-FSM!L45 -> -1349655.9 | N23: =N22*-FSM!M45 -> -1910617.4 | O23: =O22*-FSM!N45 -> -2528862.8 | P23: =P22*-FSM!O45 -> -3422228.5 | Q23: =Q22*-FSM!P45 -> -4504611.5 | ... S23: =S22*-FSM!R45 -> -7093830.9
C24: NOPAT | J24: =J22+J23 -> 1532237.9 | K24: =K22+K23 -> 2253937.4 | L24: =L22+L23 -> 3299530.6 | M24: =M22+M23 -> 4785143.6 | N24: =N22+N23 -> 6774007.3 | O24: =O22+O23 -> 9513340.9 | P24: =P22+P23 -> 12874098 | Q24: =Q22+Q23 -> 16945920 | ... S24: =S22+S23 -> 26686316
C26: Non-cash add back
C27: Depreciation and amortization | J27: =FSM!I210 -> 25239.136 | K27: =FSM!J210 -> 33966.268 | L27: =FSM!K210 -> 48413.422 | M27: =FSM!L210 -> 69840.69 | N27: =FSM!M210 -> 99829.69 | O27: =FSM!N210 -> 140141.99 | P27: =FSM!O210 -> 192491.29 | Q27: =FSM!P210 -> 257089.08 | ... S27: =FSM!R210 -> 414205.03
C29: Net working capital adjustments
C30: (Increase)/Decrease in accounts receivable | J30: =FSM!I87 -> -422893.4 | K30: =FSM!J87 -> -591271.01 | L30: =FSM!K87 -> -811833.42 | M30: =FSM!L87 -> -1089359.4 | N30: =FSM!M87 -> -1421311.1 | O30: =FSM!N87 -> -1793324.4 | P30: =FSM!O87 -> -2175026.7 | Q30: =FSM!P87 -> -2517882.2 | ... S30: =FSM!R87 -> -2819718.1
C31: (Increase)/Decrease in prepaid expenses and other current assets | J31: =FSM!I88 -> -56436.109 | K31: =FSM!J88 -> -78906.493 | L31: =FSM!K88 -> -108341.06 | M31: =FSM!L88 -> -145377.55 | N31: =FSM!M88 -> -189677.27 | O31: =FSM!N88 -> -239323.31 | P31: =FSM!O88 -> -290262.38 | Q31: =FSM!P88 -> -336017.24 | ... S31: =FSM!R88 -> -376297.94
C32: Increase/(Decrease) in accounts payable | J32: =FSM!I89 -> 3272.5525 | K32: =FSM!J89 -> 4575.5394 | L32: =FSM!K89 -> 6282.3574 | M32: =FSM!L89 -> 8429.9871 | N32: =FSM!M89 -> 10998.789 | O32: =FSM!N89 -> 13877.606 | P32: =FSM!O89 -> 16831.403 | Q32: =FSM!P89 -> 19484.583 | ... S32: =FSM!R89 -> 21820.334
C33: Increase/(Decrease) in accrued liabilities | J33: =FSM!I90 -> 144320.21 | K33: =FSM!J90 -> 201782.2 | L33: =FSM!K90 -> 277053.21 | M33: =FSM!L90 -> 371764.1 | N33: =FSM!M90 -> 485048.76 | O33: =FSM!N90 -> 612005.19 | P33: =FSM!O90 -> 742268.19 | Q33: =FSM!P90 -> 859273.99 | ... S33: =FSM!R90 -> 962281.08
C34: Increase/(Decrease in deferred revenue | J34: =FSM!I91 -> 184721.87 | K34: =FSM!J91 -> 258270.02 | L34: =FSM!K91 -> 354612.74 | M34: =FSM!L91 -> 475837.44 | N34: =FSM!M91 -> 620835.51 | O34: =FSM!N91 -> 783332.71 | P34: =FSM!O91 -> 950062.13 | Q34: =FSM!P91 -> 1099823.1 | ... S34: =FSM!R91 -> 1231666.4
C35: Increase/(Decrease) in customer deposits | J35: =FSM!I92 -> 144912.71 | K35: =FSM!J92 -> 202610.6 | L35: =FSM!K92 -> 278190.64 | M35: =FSM!L92 -> 373290.37 | N35: =FSM!M92 -> 487040.1 | O35: =FSM!N92 -> 614517.75 | P35: =FSM!O92 -> 745315.55 | Q35: =FSM!P92 -> 862801.7 | ... S35: =FSM!R92 -> 966231.68
C37: Capital expenditures
C38: Capital expenditures | J38: =-FSM!I181 -> -47632.077 | K38: =-FSM!J181 -> -66856.832 | L38: =-FSM!K181 -> -93253.017 | M38: =-FSM!L181 -> -128672.76 | N38: =-FSM!M181 -> -174885.68 | O38: =-FSM!N181 -> -233194.34 | P38: =-FSM!O181 -> -303913.78 | Q38: =-FSM!P181 -> -385780.93 | ... S38: =-FSM!R181 -> -567108.72
C39: Unlevered Free Cash Flow | J39: =J24+SUM(J27:J38) -> 1507742.8 | K39: =K24+SUM(K27:K38) -> 2218107.7 | L39: =L24+SUM(L27:L38) -> 3250655.5 | M39: =M24+SUM(M27:M38) -> 4720896.4 | N39: =N24+SUM(N27:N38) -> 6691886.1 | O39: =O24+SUM(O27:O38) -> 9411374.1 | P39: =P24+SUM(P27:P38) -> 12751863 | Q39: =Q24+SUM(Q27:Q38) -> 16804712 | ... S39: =S24+SUM(S27:S38) -> 26519396
C42: Fiscal Year | I42: Val Date | J42: 1 | K42: 2 | L42: 3 | M42: 4 | N42: 5 | O42: 6 | P42: 7 | Q42: 8 | R42: 9 | S42: 10
C43: End Date | I43: =D7 -> 46093 | J43: =IF($K$6=0,J13,AVERAGE(J13,I43)) -> 46240 | K43: =IF($K$6=0,K13,AVERAGE(K13,J13)) -> 46569.5 | L43: =IF($K$6=0,L13,AVERAGE(L13,K13)) -> 46935 | M43: =IF($K$6=0,M13,AVERAGE(M13,L13)) -> 47300.5 | N43: =IF($K$6=0,N13,AVERAGE(N13,M13)) -> 47665.5 | O43: =IF($K$6=0,O13,AVERAGE(O13,N13)) -> 48030.5 | P43: =IF($K$6=0,P13,AVERAGE(P13,O13)) -> 48396 | Q43: =IF($K$6=0,Q13,AVERAGE(Q13,P13)) -> 48761.5 | R43: =IF($K$6=0,R13,AVERAGE(R13,Q13)) -> 49126.5 | S43: =IF($K$6=0,S13,AVERAGE(S13,R13)) -> 49491.5
C45: Unlevered Free Cash Flow stub adjusted | J45: =J39*D10 -> 1210382.4 | K45: =K39 -> 2218107.7 | L45: =L39 -> 3250655.5 | M45: =M39 -> 4720896.4 | N45: =N39 -> 6691886.1 | O45: =O39 -> 9411374.1 | P45: =P39 -> 12751863 | Q45: =Q39 -> 16804712 | R45: =R39 -> 21469131 | S45: =S39 -> 26519396
C46: PV Factor | J46: =1/(1+$K$5)^((J43-$I$43)/365) -> 0.96178314 | K46: =1/(1+$K$5)^((K43-$I$43)/365) -> 0.8813424 | L46: =1/(1+$K$5)^((L43-$I$43)/365) -> 0.79995914 | M46: =1/(1+$K$5)^((M43-$I$43)/365) -> 0.72609081 | N46: =1/(1+$K$5)^((N43-$I$43)/365) -> 0.65913085 | O46: =1/(1+$K$5)^((O43-$I$43)/365) -> 0.59834592 | P46: =1/(1+$K$5)^((P43-$I$43)/365) -> 0.54309459 | Q46: =1/(1+$K$5)^((Q43-$I$43)/365) -> 0.49294516 | ... S46: =1/(1+$K$5)^((S43-$I$43)/365) -> 0.40621879
C47: PV of Unlevered Free Cash Flows | J47: =J45*J46 -> 1164125.4 | K47: =K45*K46 -> 1954912.4 | L47: =L45*L46 -> 2600391.5 | M47: =M45*M46 -> 3427799.5 | N47: =N45*N46 -> 4410828.6 | O47: =O45*O46 -> 5631257.3 | P47: =P45*P46 -> 6925467.9 | Q47: =Q45*Q46 -> 8283801.3 | ... S47: =S45*S46 -> 10772677
B50: x | C50: Terminal Value - Gordon Growth | F50: Terminal Value - Exit Multiple | K50: Net Debt | P50: Shares Outstanding
C51: Long-term growth rate | D51: 0.035 | F51: Terminal year EBITDA | I51: =FSM!R32 -> 34194352 | K51: Gross debt and equivalents | P51: Basic shares | S51: =FSM!D7 -> 2391675.7
C52: 2035 FCF x (1+g) | D52: =S39*(1+D51) -> 27447575 | F52: EBITDA multiple | I52: =Valuation!P14 -> 35.893007 | K52: Debt | N52: 0 | P52: Restricted stock/RSUs | S52: 41762
...

Sheet Comps>>>

Sheet Inputs
C2: Comparable Company Inputs
C3: $USD Thousand except per share data
C5: Refresh Date | D5: 46093
C6: Recent Calendarized Date | D6: 46022
B8: x | C8: General Inputs
C10: Ticker | D10: NASDAQ: DDOG | F10: NYSE: SNOW | H10: NYSE: HUBS | J10: NYSE: CRM | L10: NYSE: ORCL | N10: NASDAQ: PANW
C11: Company name | D11: Datadog | F11: Snowflake | H11: Hubspot | J11: Salesforce | L11: Oracle | N11: Palo Alto Networks
C12: Lastest closing price | D12: 127.16 | F12: 177.25 | H12: 257.63 | J12: 199.28 | L12: 159.16 | N12: 168.13
C13: Latest fiscal year end | D13: 46022 | F13: 45688 | H13: 46022 | J13: 46053 | L13: 45808 | N13: 45869
C14: Latest quarter year end | D14: 46022 | F14: 45961 | H14: 46022 | J14: 46053 | L14: 46081 | N14: 46053
B17: x | C17: Share Counts
C19: Basic share count | D19: 352576.08 | F19: 342200 | H19: 52740.536 | J19: 923000 | L19: 2876046 | N19: 816000
C20: RSUs/PSUs | D20: 16700.403 | F20: 24039 | H20: 1471 | J20: 22000 | L20: 120000 | N20: 22000
C21: Total Basic Share Count | D21: =SUM(D19:D20) -> 369276.48 | F21: =SUM(F19:F20) -> 366239 | H21: =SUM(H19:H20) -> 54211.536 | J21: =SUM(J19:J20) -> 945000 | L21: =SUM(L19:L20) -> 2996046 | N21: =SUM(N19:N20) -> 838000
C23: Options count | D23: 3474.619 | F23: 13695 | H23: 174 | J23: 6000 | L23: 41000 | N23: 0
C24: Weighted average exercise price | D24: 7.26 | F24: 18.83 | H24: 286.89 | J24: 207.54 | L24: 52.58 | N24: 0
C25: # of options exercised | D25: =IF(D24<D12,D23,0) -> 3474.619 | F25: =IF(F24<F12,F23,0) -> 13695 | H25: =IF(H24<H12,H23,0) -> 0 | J25: =IF(J24<J12,J23,0) -> 0 | L25: =IF(L24<L12,L23,0) -> 41000 | N25: =IF(N24<N12,N23,0) -> 0
C26: Option proceeds | D26: =D25*D24 -> 25225.734 | F26: =F25*F24 -> 257876.85 | H26: =H25*H24 -> 0 | J26: =J25*J24 -> 0 | L26: =L25*L24 -> 2155780 | N26: =N25*N24 -> 0
C27: Shares repurchased | D27: =D26/D12 -> 198.3779 | F27: =F26/F12 -> 1454.8764 | H27: =H26/H12 -> 0 | J27: =J26/J12 -> 0 | L27: =L26/L12 -> 13544.735 | N27: =N26/N12 -> 0
C28: Net Dilution from Options | D28: =D25-D27 -> 3276.2411 | F28: =F25-F27 -> 12240.124 | H28: =H25-H27 -> 0 | J28: =J25-J27 -> 0 | L28: =L25-L27 -> 27455.265 | N28: =N25-N27 -> 0
C30: Convertible debt outstanding | D30: 983449 | F30: 2277749 | H30: 0 | J30: 0 | L30: 0 | N30: 0
C31: Conversion ratio | D31: 4.5955 | F31: 6.3492 | H31: 3.5396 | J31: 0 | L31: 0 | N31: 0
C32: Conversion price | D32: =D30/D33 -> 217.60418 | F32: =F30/F33 -> 157.50016 | H32: 0 | J32: 0 | L32: 0 | N32: 0
C33: Common shares convertible into | D33: =D30*D31/1000 -> 4519.4399 | F33: =F30*F31/1000 -> 14461.884 | H33: 0 | J33: 0 | L33: 0 | N33: 0
C34: Dilution from convertible debt | D34: =IF(D32<D12,D33,0) -> 0 | F34: =IF(F32<F12,F33,0) -> 14461.884 | H34: =IF(H32<H12,H33,0) -> 0 | J34: =IF(J32<J12,J33,0) -> 0 | L34: =IF(L32<L12,L33,0) -> 0 | N34: =IF(N32<N12,N33,0) -> 0
C36: Convertible preferred par value | D36: 0 | F36: 0 | H36: 0 | J36: 0 | L36: 4954000 | N36: 0
C37: Preferred shares oustanding | D37: 0 | F37: 0 | H37: 0 | J37: 0 | L37: 50000 | N37: 0
C38: Conversion ratio | D38: 0 | F38: 0 | H38: 0 | J38: 0 | L38: 499.8126 | N38: 0
C39: Common shares convertible into | D39: 0 | F39: 0 | H39: 0 | J39: 0 | L39: =L37*L38 -> 24990630 | N39: 0
C40: Conversion price | D40: 0 | F40: 0 | H40: 0 | J40: 0 | L40: 0 | N40: 0
C41: Dilution from preferred stock | D41: 0 | F41: 0 | H41: 0 | J41: 0 | L41: 0 | N41: 0
C43: Fully Diluted Shares Outstanding | D43: =D21+D28+D34 -> 372552.73 | F43: =F21+F28+F34 -> 392941.01 | H43: =H21+H28+H34 -> 54211.536 | J43: =J21+J28+J34 -> 945000 | L43: =L21+L28+L34 -> 3023501.3 | N43: =N21+N28+N34 -> 838000
B46: x | C46: Balance Sheet Data
C48: Cash | D48: 401305 | F48: 1941657 | H48: 882242 | J48: 7327000 | L48: 38455000 | N48: 4158000
C49: Investments | D49: 4073531 | F49: 1411448 | H49: 958214 | J49: 2238000 | L49: 677000 | N49: 378000
C50: Cash & Cash Equivalents | D50: =SUM(D48:D49) -> 4474836 | F50: =SUM(F48:F49) -> 3353105 | H50: =SUM(H48:H49) -> 1840456 | J50: =SUM(J48:J49) -> 9565000 | L50: =SUM(L48:L49) -> 39132000 | N50: =SUM(N48:N49) -> 4536000
C51: Accounts Receivable | D51: 741262 | F51: 938145 | H51: 419146 | J51: 14339000 | L51: 10719000 | N51: 2116000
C52: Prepaid expenses & other current assets | D52: 90160 | F52: 164319 | H52: 100611 | J52: 2243000 | L52: 5023000 | N52: 621000
C53: Goodwill & Intangibles | D53: 545536 | F53: 1431540 | H53: 326677 | J53: 64756000 | L53: 65915000 | N53: 8180000
C54: Operating lease assets | D54: 214674 | F54: 254641 | H54: 200821 | J54: 2003000 | L54: 20817000 | N54: 368000
...

Sheet Operating Metrics
C2: Comparable Company Operating Metrics
C3: $USD Thousand except per share data
J5: Revenue | O5: CAGR | Q5: Adjusted EBIT | V5: CAGR | X5: Adjusted EBIT Margin | AC5: Adjusted EBITDA | AH5: CAGR | AJ5: Adjusted EBITDA Margin | AO5: Adjusted Net Income | AT5: CAGR | AV5: Adjusted Net Income Margin
C6: Ticker | D6: Company | E6: Enterprise Value | F6: Market Capitalization | G6: Price | H6: Net Debt/ LTM EBITDA | J6: 0 | K6: LTM | L6: 1 | M6: 2 | O6: FY0-FY2 | Q6: 0 | R6: LTM | S6: 1 | T6: 2 | V6: FY0-FY2 | X6: 0 | Y6: LTM | Z6: 1 | AA6: 2 | AC6: 0 | AD6: LTM | AE6: 1 | AF6: 2 | AH6: FY0-FY2 | AJ6: 0 | AK6: LTM | AL6: 1 | AM6: 2 | AO6: 0 | AP6: LTM | AQ6: 1 | AR6: 2 | AT6: FY0-FY2 | AV6: 0 | AW6: LTM | AX6: 1 | AY6: 2
C7: NASDAQ: DDOG | D7: =_xlfn.XLOOKUP(C7,Inputs!$D$10:$N$10,Inputs!$D$11:$N$11) -> Datadog | E7: =_xlfn.XLOOKUP(C7,Inputs!$D$10:$N$10,Inputs!$D$86:$N$86) -> 44177974 | F7: =_xlfn.XLOOKUP(C7,Inputs!$D$10:$N$10,Inputs!$D$77:$N$77) -> 47373805 | G7: =_xlfn.XLOOKUP(C7,Inputs!$D$10:$N$10,Inputs!$D$12:$N$12) -> 127.16 | H7: =_xlfn.XLOOKUP(C7,Inputs!$D$10:$N$10,Inputs!$D$84:$N$84)/'Operating Metrics'!AD7 -> -3.8793773 | J7: =_xlfn.XLOOKUP(C7,Inputs!$D$10:$N$10,Inputs!$D$184:$N$184) -> 3427158 | K7: =_xlfn.XLOOKUP(C7,Inputs!$D$10:$N$10,Inputs!$D$173:$N$173) -> 3427158 | L7: =_xlfn.XLOOKUP(C7,Inputs!$D$10:$N$10,Inputs!$D$185:$N$185) -> 4121580 | M7: =_xlfn.XLOOKUP(C7,Inputs!$D$10:$N$10,Inputs!$D$186:$N$186) -> 4930010 | O7: =(M7/J7)^(1/($M$6-$J$6))-1 -> 0.19938009 | Q7: =_xlfn.XLOOKUP(C7,Inputs!$D$10:$N$10,Inputs!$D$200:$N$200) -> 768044 | R7: =_xlfn.XLOOKUP(C7,Inputs!$D$10:$N$10,Inputs!$D$175:$N$175) -> 768044 | S7: =_xlfn.XLOOKUP(C7,Inputs!$D$10:$N$10,Inputs!$D$201:$N$201) -> 879310 | T7: =_xlfn.XLOOKUP(C7,Inputs!$D$10:$N$10,Inputs!$D$202:$N$202) -> 1113080 | V7: =(T7/Q7)^(1/($T$6-$Q$6))-1 -> 0.2038438 | X7: =Q7/J7 -> 0.22410522 | Y7: =R7/K7 -> 0.22410522 | Z7: =S7/L7 -> 0.21334294 | AA7: =T7/M7 -> 0.22577642 | AC7: =_xlfn.XLOOKUP(C7,Inputs!$D$10:$N$10,Inputs!$D$192:$N$192) -> 823800 | AD7: =_xlfn.XLOOKUP(C7,Inputs!$D$10:$N$10,Inputs!$D$174:$N$174) -> 823800 | AE7: =_xlfn.XLOOKUP(C7,Inputs!$D$10:$N$10,Inputs!$D$193:$N$193) -> 987200 | AF7: =_xlfn.XLOOKUP(C7,Inputs!$D$10:$N$10,Inputs!$D$194:$N$194) -> 1221230 | AH7: =(AF7/AC7)^(1/($AF$6-$AC$6))-1 -> 0.2175529 | AJ7: =AC7/J7 -> 0.24037409 | AK7: =AD7/K7 -> 0.24037409 | AL7: =AE7/L7 -> 0.2395198 | AM7: =AF7/M7 -> 0.24771349 | AO7: =_xlfn.XLOOKUP(C7,Inputs!$D$10:$N$10,Inputs!$D$208:$N$208) -> 746582 | AP7: =_xlfn.XLOOKUP(C7,Inputs!$D$10:$N$10,Inputs!$D$176:$N$176) -> 746582 | AQ7: =_xlfn.XLOOKUP(C7,Inputs!$D$10:$N$10,Inputs!$D$209:$N$209) -> 797830 | AR7: =_xlfn.XLOOKUP(C7,Inputs!$D$10:$N$10,Inputs!$D$210:$N$210) -> 1019470 | AT7: =(AR7/AO7)^(1/($AR$6-$AO$6))-1 -> 0.16855314 | AV7: =AO7/J7 -> 0.21784289 | AW7: =AP7/K7 -> 0.21784289 | AX7: =AQ7/L7 -> 0.19357382 | AY7: =AR7/M7 -> 0.20678863
C8: NYSE: SNOW | D8: =_xlfn.XLOOKUP(C8,Inputs!$D$10:$N$10,Inputs!$D$11:$N$11) -> Snowflake | E8: =_xlfn.XLOOKUP(C8,Inputs!$D$10:$N$10,Inputs!$D$86:$N$86) -> 66703555 | F8: =_xlfn.XLOOKUP(C8,Inputs!$D$10:$N$10,Inputs!$D$77:$N$77) -> 69648794 | G8: =_xlfn.XLOOKUP(C8,Inputs!$D$10:$N$10,Inputs!$D$12:$N$12) -> 177.25 | H8: =_xlfn.XLOOKUP(C8,Inputs!$D$10:$N$10,Inputs!$D$84:$N$84)/'Operating Metrics'!AD8 -> -3.3011454 | J8: =_xlfn.XLOOKUP(C8,Inputs!$D$10:$N$10,Inputs!$D$184:$N$184) -> 3626396 | K8: =_xlfn.XLOOKUP(C8,Inputs!$D$10:$N$10,Inputs!$D$173:$N$173) -> 4386722 | L8: =_xlfn.XLOOKUP(C8,Inputs!$D$10:$N$10,Inputs!$D$185:$N$185) -> 4683950 | M8: =_xlfn.XLOOKUP(C8,Inputs!$D$10:$N$10,Inputs!$D$186:$N$186) -> 5917810 | O8: =(M8/J8)^(1/($M$6-$J$6))-1 -> 0.27744701 | Q8: =_xlfn.XLOOKUP(C8,Inputs!$D$10:$N$10,Inputs!$D$200:$N$200) -> 468873 | R8: =_xlfn.XLOOKUP(C8,Inputs!$D$10:$N$10,Inputs!$D$175:$N$175) -> 680538 | S8: =_xlfn.XLOOKUP(C8,Inputs!$D$10:$N$10,Inputs!$D$201:$N$201) -> 489720 | T8: =_xlfn.XLOOKUP(C8,Inputs!$D$10:$N$10,Inputs!$D$202:$N$202) -> 739500 | V8: =(T8/Q8)^(1/($T$6-$Q$6))-1 -> 0.25586072 | X8: =Q8/J8 -> 0.12929448 | Y8: =R8/K8 -> 0.15513589 | Z8: =S8/L8 -> 0.10455278 | AA8: =T8/M8 -> 0.12496177 | AC8: =_xlfn.XLOOKUP(C8,Inputs!$D$10:$N$10,Inputs!$D$192:$N$192) -> 651381 | AD8: =_xlfn.XLOOKUP(C8,Inputs!$D$10:$N$10,Inputs!$D$174:$N$174) -> 892187 | AE8: =_xlfn.XLOOKUP(C8,Inputs!$D$10:$N$10,Inputs!$D$193:$N$193) -> 710160 | AF8: =_xlfn.XLOOKUP(C8,Inputs!$D$10:$N$10,Inputs!$D$194:$N$194) -> 909340 | AH8: =(AF8/AC8)^(1/($AF$6-$AC$6))-1 -> 0.18153232 | AJ8: =AC8/J8 -> 0.17962214 | AK8: =AD8/K8 -> 0.20338353 | AL8: =AE8/L8 -> 0.15161562 | AM8: =AF8/M8 -> 0.15366157 | AO8: =_xlfn.XLOOKUP(C8,Inputs!$D$10:$N$10,Inputs!$D$208:$N$208) -> 514002 | AP8: =_xlfn.XLOOKUP(C8,Inputs!$D$10:$N$10,Inputs!$D$176:$N$176) -> 657078 | AQ8: =_xlfn.XLOOKUP(C8,Inputs!$D$10:$N$10,Inputs!$D$209:$N$209) -> 670010 | AR8: =_xlfn.XLOOKUP(C8,Inputs!$D$10:$N$10,Inputs!$D$210:$N$210) -> 926220 | AT8: =(AR8/AO8)^(1/($AR$6-$AO$6))-1 -> 0.34237753 | AV8: =AO8/J8 -> 0.14173907 | AW8: =AP8/K8 -> 0.14978793 | AX8: =AQ8/L8 -> 0.1430438 | AY8: =AR8/M8 -> 0.15651398
C9: NYSE: HUBS | D9: =_xlfn.XLOOKUP(C9,Inputs!$D$10:$N$10,Inputs!$D$11:$N$11) -> Hubspot | E9: =_xlfn.XLOOKUP(C9,Inputs!$D$10:$N$10,Inputs!$D$86:$N$86) -> 12388367 | F9: =_xlfn.XLOOKUP(C9,Inputs!$D$10:$N$10,Inputs!$D$77:$N$77) -> 13966518 | G9: =_xlfn.XLOOKUP(C9,Inputs!$D$10:$N$10,Inputs!$D$12:$N$12) -> 257.63 | H9: =_xlfn.XLOOKUP(C9,Inputs!$D$10:$N$10,Inputs!$D$84:$N$84)/'Operating Metrics'!AD9 -> -2.1973821 | J9: =_xlfn.XLOOKUP(C9,Inputs!$D$10:$N$10,Inputs!$D$184:$N$184) -> 3131266 | K9: =_xlfn.XLOOKUP(C9,Inputs!$D$10:$N$10,Inputs!$D$173:$N$173) -> 3131266 | L9: =_xlfn.XLOOKUP(C9,Inputs!$D$10:$N$10,Inputs!$D$185:$N$185) -> 3696350 | M9: =_xlfn.XLOOKUP(C9,Inputs!$D$10:$N$10,Inputs!$D$186:$N$186) -> 4286170 | O9: =(M9/J9)^(1/($M$6-$J$6))-1 -> 0.16996997 | Q9: =_xlfn.XLOOKUP(C9,Inputs!$D$10:$N$10,Inputs!$D$200:$N$200) -> 581901 | R9: =_xlfn.XLOOKUP(C9,Inputs!$D$10:$N$10,Inputs!$D$175:$N$175) -> 581901 | S9: =_xlfn.XLOOKUP(C9,Inputs!$D$10:$N$10,Inputs!$D$201:$N$201) -> 740300 | T9: =_xlfn.XLOOKUP(C9,Inputs!$D$10:$N$10,Inputs!$D$202:$N$202) -> 907850 | V9: =(T9/Q9)^(1/($T$6-$Q$6))-1 -> 0.24905769 | X9: =Q9/J9 -> 0.1858357 | Y9: =R9/K9 -> 0.1858357 | Z9: =S9/L9 -> 0.20027865 | AA9: =T9/M9 -> 0.21180914 | AC9: =_xlfn.XLOOKUP(C9,Inputs!$D$10:$N$10,Inputs!$D$192:$N$192) -> 718196 | AD9: =_xlfn.XLOOKUP(C9,Inputs!$D$10:$N$10,Inputs!$D$174:$N$174) -> 718196 | AE9: =_xlfn.XLOOKUP(C9,Inputs!$D$10:$N$10,Inputs!$D$193:$N$193) -> 877440 | AF9: =_xlfn.XLOOKUP(C9,Inputs!$D$10:$N$10,Inputs!$D$194:$N$194) -> 1067570 | AH9: =(AF9/AC9)^(1/($AF$6-$AC$6))-1 -> 0.21920487 | AJ9: =AC9/J9 -> 0.22936282 | AK9: =AD9/K9 -> 0.22936282 | AL9: =AE9/L9 -> 0.23738012 | AM9: =AF9/M9 -> 0.24907318 | AO9: =_xlfn.XLOOKUP(C9,Inputs!$D$10:$N$10,Inputs!$D$208:$N$208) -> 515988 | AP9: =_xlfn.XLOOKUP(C9,Inputs!$D$10:$N$10,Inputs!$D$176:$N$176) -> 515988 | AQ9: =_xlfn.XLOOKUP(C9,Inputs!$D$10:$N$10,Inputs!$D$209:$N$209) -> 646520 | AR9: =_xlfn.XLOOKUP(C9,Inputs!$D$10:$N$10,Inputs!$D$210:$N$210) -> 793660 | AT9: =(AR9/AO9)^(1/($AR$6-$AO$6))-1 -> 0.24021633 | AV9: =AO9/J9 -> 0.16478574 | AW9: =AP9/K9 -> 0.16478574 | AX9: =AQ9/L9 -> 0.17490768 | AY9: =AR9/M9 -> 0.18516764
C10: NYSE: CRM | D10: =_xlfn.XLOOKUP(C10,Inputs!$D$10:$N$10,Inputs!$D$11:$N$11) -> Salesforce | E10: =_xlfn.XLOOKUP(C10,Inputs!$D$10:$N$10,Inputs!$D$86:$N$86) -> 195930600 | F10: =_xlfn.XLOOKUP(C10,Inputs!$D$10:$N$10,Inputs!$D$77:$N$77) -> 188319600 | G10: =_xlfn.XLOOKUP(C10,Inputs!$D$10:$N$10,Inputs!$D$12:$N$12) -> 199.28 | H10: =_xlfn.XLOOKUP(C10,Inputs!$D$10:$N$10,Inputs!$D$84:$N$84)/'Operating Metrics'!AD10 -> 0.42789678 | J10: =_xlfn.XLOOKUP(C10,Inputs!$D$10:$N$10,Inputs!$D$184:$N$184) -> 41525000 | K10: =_xlfn.XLOOKUP(C10,Inputs!$D$10:$N$10,Inputs!$D$173:$N$173) -> 41525000 | L10: =_xlfn.XLOOKUP(C10,Inputs!$D$10:$N$10,Inputs!$D$185:$N$185) -> 46128890 | M10: =_xlfn.XLOOKUP(C10,Inputs!$D$10:$N$10,Inputs!$D$186:$N$186) -> 50529780 | O10: =(M10/J10)^(1/($M$6-$J$6))-1 -> 0.10311016 | Q10: =_xlfn.XLOOKUP(C10,Inputs!$D$10:$N$10,Inputs!$D$200:$N$200) -> 14156000 | R10: =_xlfn.XLOOKUP(C10,Inputs!$D$10:$N$10,Inputs!$D$175:$N$175) -> 14156000 | S10: =_xlfn.XLOOKUP(C10,Inputs!$D$10:$N$10,Inputs!$D$201:$N$201) -> 15874340 | T10: =_xlfn.XLOOKUP(C10,Inputs!$D$10:$N$10,Inputs!$D$202:$N$202) -> 17848180 | V10: =(T10/Q10)^(1/($T$6-$Q$6))-1 -> 0.12286279 | X10: =Q10/J10 -> 0.34090307 | Y10: =R10/K10 -> 0.34090307 | Z10: =S10/L10 -> 0.34413011 | AA10: =T10/M10 -> 0.35322101 | AC10: =_xlfn.XLOOKUP(C10,Inputs!$D$10:$N$10,Inputs!$D$192:$N$192) -> 17787000 | AD10: =_xlfn.XLOOKUP(C10,Inputs!$D$10:$N$10,Inputs!$D$174:$N$174) -> 17787000 | AE10: =_xlfn.XLOOKUP(C10,Inputs!$D$10:$N$10,Inputs!$D$193:$N$193) -> 18191960 | AF10: =_xlfn.XLOOKUP(C10,Inputs!$D$10:$N$10,Inputs!$D$194:$N$194) -> 19354770 | AH10: =(AF10/AC10)^(1/($AF$6-$AC$6))-1 -> 0.043140134 | AJ10: =AC10/J10 -> 0.42834437 | AK10: =AD10/K10 -> 0.42834437 | AL10: =AE10/L10 -> 0.39437238 | AM10: =AF10/M10 -> 0.38303689 | AO10: =_xlfn.XLOOKUP(C10,Inputs!$D$10:$N$10,Inputs!$D$208:$N$208) -> 11969000 | AP10: =_xlfn.XLOOKUP(C10,Inputs!$D$10:$N$10,Inputs!$D$176:$N$176) -> 11969000 | AQ10: =_xlfn.XLOOKUP(C10,Inputs!$D$10:$N$10,Inputs!$D$209:$N$209) -> 12360630 | AR10: =_xlfn.XLOOKUP(C10,Inputs!$D$10:$N$10,Inputs!$D$210:$N$210) -> 13906060 | AT10: =(AR10/AO10)^(1/($AR$6-$AO$6))-1 -> 0.077886707 | AV10: =AO10/J10 -> 0.288236 | AW10: =AP10/K10 -> 0.288236 | AX10: =AQ10/L10 -> 0.26795854 | AY10: =AR10/M10 -> 0.27520524
C11: NYSE: ORCL | D11: =_xlfn.XLOOKUP(C11,Inputs!$D$10:$N$10,Inputs!$D$11:$N$11) -> Oracle | E11: =_xlfn.XLOOKUP(C11,Inputs!$D$10:$N$10,Inputs!$D$86:$N$86) -> 6.0351346e+08 | F11: =_xlfn.XLOOKUP(C11,Inputs!$D$10:$N$10,Inputs!$D$77:$N$77) -> 4.8122046e+08 | G11: =_xlfn.XLOOKUP(C11,Inputs!$D$10:$N$10,Inputs!$D$12:$N$12) -> 159.16 | H11: =_xlfn.XLOOKUP(C11,Inputs!$D$10:$N$10,Inputs!$D$84:$N$84)/'Operating Metrics'!AD11 -> 3.4435152 | J11: =_xlfn.XLOOKUP(C11,Inputs!$D$10:$N$10,Inputs!$D$184:$N$184) -> 57399000 | K11: =_xlfn.XLOOKUP(C11,Inputs!$D$10:$N$10,Inputs!$D$173:$N$173) -> 64076000 | L11: =_xlfn.XLOOKUP(C11,Inputs!$D$10:$N$10,Inputs!$D$185:$N$185) -> 67119090 | M11: =_xlfn.XLOOKUP(C11,Inputs!$D$10:$N$10,Inputs!$D$186:$N$186) -> 88996530 | O11: =(M11/J11)^(1/($M$6-$J$6))-1 -> 0.24518641 | Q11: =_xlfn.XLOOKUP(C11,Inputs!$D$10:$N$10,Inputs!$D$200:$N$200) -> 25033000 | R11: =_xlfn.XLOOKUP(C11,Inputs!$D$10:$N$10,Inputs!$D$175:$N$175) -> 27371000 | S11: =_xlfn.XLOOKUP(C11,Inputs!$D$10:$N$10,Inputs!$D$201:$N$201) -> 28536000 | T11: =_xlfn.XLOOKUP(C11,Inputs!$D$10:$N$10,Inputs!$D$202:$N$202) -> 34665560 | V11: =(T11/Q11)^(1/($T$6-$Q$6))-1 -> 0.17677291 | X11: =Q11/J11 -> 0.43612258 | Y11: =R11/K11 -> 0.42716462 | Z11: =S11/L11 -> 0.42515475 | AA11: =T11/M11 -> 0.38951586 | AC11: =_xlfn.XLOOKUP(C11,Inputs!$D$10:$N$10,Inputs!$D$192:$N$192) -> 31207000 | AD11: =_xlfn.XLOOKUP(C11,Inputs!$D$10:$N$10,Inputs!$D$174:$N$174) -> 35514000 | AE11: =_xlfn.XLOOKUP(C11,Inputs!$D$10:$N$10,Inputs!$D$193:$N$193) -> 36359120 | AF11: =_xlfn.XLOOKUP(C11,Inputs!$D$10:$N$10,Inputs!$D$194:$N$194) -> 45937920 | AH11: =(AF11/AC11)^(1/($AF$6-$AC$6))-1 -> 0.21327613 | AJ11: =AC11/J11 -> 0.54368543 | AK11: =AD11/K11 -> 0.55424808 | AL11: =AE11/L11 -> 0.54171056 | AM11: =AF11/M11 -> 0.51617653 | AO11: =_xlfn.XLOOKUP(C11,Inputs!$D$10:$N$10,Inputs!$D$208:$N$208) -> 17284000 | AP11: =_xlfn.XLOOKUP(C11,Inputs!$D$10:$N$10,Inputs!$D$176:$N$176) -> 20984000 | AQ11: =_xlfn.XLOOKUP(C11,Inputs!$D$10:$N$10,Inputs!$D$209:$N$209) -> 21860860 | AR11: =_xlfn.XLOOKUP(C11,Inputs!$D$10:$N$10,Inputs!$D$210:$N$210) -> 23799820 | AT11: =(AR11/AO11)^(1/($AR$6-$AO$6))-1 -> 0.17345032 | AV11: =AO11/J11 -> 0.30112023 | AW11: =AP11/K11 -> 0.32748611 | AX11: =AQ11/L11 -> 0.32570257 | AY11: =AR11/M11 -> 0.26742413
